Workbook

Sheet 情報入力
A1: 情報入力
A3: 基本情報
A4: 大項目 | B4: 項目名 | C4: 入力値 | D4: 補足
A5: 基本情報 | B5: プラン作成日
B6: ご家庭名
B7: 担当者名
B8: ご主人様のお名前
B9: 奥様のお名前
B10: ご主人様の生年月日
B11: 奥様の生年月日
B12: お住まいの都道府県
B13: 住まい区分 | D13: 持ち家 / 賃貸
A15: 家族情報
A16: 大項目 | B16: 項目名 | C16: 入力値 | D16: 補足
A17: 家族情報 | B17: お子さま人数 | D17: 0〜3人
B18: お子さま1 お名前
B19: お子さま1 生年月日
B20: お子さま2 お名前
B21: お子さま2 生年月日
B22: お子さま3 お名前
B23: お子さま3 生年月日
A24: 収入情報
A25: 大項目 | B25: 項目名 | C25: 入力値 | D25: 補足
A26: 収入情報 | B26: ご主人様の働き方
B27: 奥様の働き方
B28: ご主人様の毎月手取り収入 | D28: 円
B29: 奥様の毎月手取り収入 | D29: 円
B30: 賞与の有無 | D30: あり / なし
B31: ご主人様の年間賞与手取り | D31: 円
B32: 奥様の年間賞与手取り | D32: 円
B33: 児童手当（月額） | D33: 未入力なら平均額を自動反映
B34: その他の定期収入（月額） | D34: 未入力なら0円
B35: ご主人様の退職金見込額 | D35: 未入力なら0円
B36: 奥様の退職金見込額 | D36: 未入力なら0円
A38: 支出情報（主要）
A39: 大項目 | B39: 項目名 | C39: 入力値 | D39: 補足
A40: 支出情報（月額） | B40: 毎月の食費 | D40: 円
B41: 毎月の日用品費 | D41: 円
B42: 毎月の水道・光熱費 | D42: 円
B43: 毎月の通信費 | D43: 円
...

Sheet 前提条件
A1: 前提条件
A3: 昇給率
A4: 大項目 | B4: 項目名 | C4: 入力値 | D4: 補足
A5: 昇給率 | B5: ご主人様収入上昇率 | C5: 0
A6: 昇給率 | B6: 奥様収入上昇率 | C6: 0
A7: 昇給率 | B7: 賞与上昇率 | C7: 0
A8: 昇給率 | B8: 児童手当終了年齢 | C8: 18
A10: 物価上昇率
A11: 大項目 | B11: 項目名 | C11: 入力値 | D11: 補足
A12: 物価上昇率 | B12: 基本生活費上昇率 | C12: 0
A13: 物価上昇率 | B13: 教育費上昇率 | C13: 0
A14: 物価上昇率 | B14: 老後生活費上昇率 | C14: 0
A15: 物価上昇率 | B15: 住宅費上昇率 | C15: 0
A16: 物価上昇率 | B16: 老後インフレ率① | C16: 0
A17: 物価上昇率 | B17: 老後インフレ率② | C17: 0
A19: 教育費単価マスタ
A20: 大項目 | B20: 項目名 | C20: 入力値 | D20: 補足
A21: 教育費単価マスタ | B21: 幼稚園公立年額 | C21: 300000
A22: 教育費単価マスタ | B22: 幼稚園私立年額 | C22: 700000
A23: 教育費単価マスタ | B23: 小学校公立年額 | C23: 400000
A24: 教育費単価マスタ | B24: 小学校私立年額 | C24: 1800000
A25: 教育費単価マスタ | B25: 中学校公立年額 | C25: 550000
A26: 教育費単価マスタ | B26: 中学校私立年額 | C26: 1600000
A27: 教育費単価マスタ | B27: 高校公立年額 | C27: 600000
A28: 教育費単価マスタ | B28: 高校私立年額 | C28: 1200000
A29: 教育費単価マスタ | B29: 大学国公立年額 | C29: 1400000
A30: 教育費単価マスタ | B30: 大学私立文系年額 | C30: 2200000
A31: 教育費単価マスタ | B31: 大学私立理系年額 | C31: 2800000
A32: 教育費単価マスタ | B32: 下宿加算年額 | C32: 1200000
A33: 教育費単価マスタ | B33: 大学入学一時金 | C33: 300000
A35: 年金前提
A36: 大項目 | B36: 項目名 | C36: 入力値 | D36: 補足
A37: 年金前提 | B37: ご主人様年金開始年齢 | C37: 65
A38: 年金前提 | B38: 奥様年金開始年齢 | C38: 65
A39: 年金前提 | B39: ご主人様年金月額 | C39: =IFERROR(ROUND(((IF(入力データ!$C$29="",0,入力データ!$C$29)*12)+IF(入力データ!$C$31="あり",IF(入力データ!$C$32="",0,入力データ!$C$32),0))*0.2/12,0),0) | D39: 現在年収の20%を月額換算
A40: 年金前提 | B40: 奥様年金月額 | C40: =IFERROR(ROUND(((IF(入力データ!$C$30="",0,入力データ!$C$30)*12)+IF(入力データ!$C$31="あり",IF(入力データ!$C$33="",0,入力データ!$C$33),0))*0.2/12,0),0) | D40: 現在年収の20%を月額換算
A42: 住宅前提
A43: 大項目 | B43: 項目名 | C43: 入力値 | D43: 補足
A44: 住宅前提 | B44: 住宅ローン完済年齢 | C44: 60
A45: 住宅前提 | B45: 住宅ローン金利 | C45: 0.012
...

Sheet CF表（万円表示）
A1: CF表（万円表示）
A2: 試算終了年 | B2: =CF表!B2
A3: 年 | B3: =IF(CF表!B3="","",CF表!B3) | C3: =IF(CF表!C3="","",CF表!C3) | D3: =IF(CF表!D3="","",CF表!D3) | E3: =IF(CF表!E3="","",CF表!E3) | F3: =IF(CF表!F3="","",CF表!F3) | G3: =IF(CF表!G3="","",CF表!G3) | H3: =IF(CF表!H3="","",CF表!H3) | I3: =IF(CF表!I3="","",CF表!I3) | ... CW3: =IF(CF表!CW3="","",CF表!CW3)
A4: ご主人様年齢 | B4: =IF(CF表!B4="","",CF表!B4) | C4: =IF(CF表!C4="","",CF表!C4) | D4: =IF(CF表!D4="","",CF表!D4) | E4: =IF(CF表!E4="","",CF表!E4) | F4: =IF(CF表!F4="","",CF表!F4) | G4: =IF(CF表!G4="","",CF表!G4) | H4: =IF(CF表!H4="","",CF表!H4) | I4: =IF(CF表!I4="","",CF表!I4) | ... CW4: =IF(CF表!CW4="","",CF表!CW4)
A5: 奥様年齢 | B5: =IF(CF表!B5="","",CF表!B5) | C5: =IF(CF表!C5="","",CF表!C5) | D5: =IF(CF表!D5="","",CF表!D5) | E5: =IF(CF表!E5="","",CF表!E5) | F5: =IF(CF表!F5="","",CF表!F5) | G5: =IF(CF表!G5="","",CF表!G5) | H5: =IF(CF表!H5="","",CF表!H5) | I5: =IF(CF表!I5="","",CF表!I5) | ... CW5: =IF(CF表!CW5="","",CF表!CW5)
A6: 子1年齢 | B6: =IF(CF表!B6="","",CF表!B6) | C6: =IF(CF表!C6="","",CF表!C6) | D6: =IF(CF表!D6="","",CF表!D6) | E6: =IF(CF表!E6="","",CF表!E6) | F6: =IF(CF表!F6="","",CF表!F6) | G6: =IF(CF表!G6="","",CF表!G6) | H6: =IF(CF表!H6="","",CF表!H6) | I6: =IF(CF表!I6="","",CF表!I6) | ... CW6: =IF(CF表!CW6="","",CF表!CW6)
A7: 子2年齢 | B7: =IF(CF表!B7="","",CF表!B7) | C7: =IF(CF表!C7="","",CF表!C7) | D7: =IF(CF表!D7="","",CF表!D7) | E7: =IF(CF表!E7="","",CF表!E7) | F7: =IF(CF表!F7="","",CF表!F7) | G7: =IF(CF表!G7="","",CF表!G7) | H7: =IF(CF表!H7="","",CF表!H7) | I7: =IF(CF表!I7="","",CF表!I7) | ... CW7: =IF(CF表!CW7="","",CF表!CW7)
A8: 子3年齢 | B8: =IF(CF表!B8="","",CF表!B8) | C8: =IF(CF表!C8="","",CF表!C8) | D8: =IF(CF表!D8="","",CF表!D8) | E8: =IF(CF表!E8="","",CF表!E8) | F8: =IF(CF表!F8="","",CF表!F8) | G8: =IF(CF表!G8="","",CF表!G8) | H8: =IF(CF表!H8="","",CF表!H8) | I8: =IF(CF表!I8="","",CF表!I8) | ... CW8: =IF(CF表!CW8="","",CF表!CW8)
A9: 家族年齢
A10: ご主人様収入 | B10: =IF(CF表!B$3="","",CF表!B10/10000) | C10: =IF(CF表!C$3="","",CF表!C10/10000) | D10: =IF(CF表!D$3="","",CF表!D10/10000) | E10: =IF(CF表!E$3="","",CF表!E10/10000) | F10: =IF(CF表!F$3="","",CF表!F10/10000) | G10: =IF(CF表!G$3="","",CF表!G10/10000) | H10: =IF(CF表!H$3="","",CF表!H10/10000) | I10: =IF(CF表!I$3="","",CF表!I10/10000) | ... CW10: =IF(CF表!CW$3="","",CF表!CW10/10000)
A11: 奥様収入 | B11: =IF(CF表!B$3="","",CF表!B11/10000) | C11: =IF(CF表!C$3="","",CF表!C11/10000) | D11: =IF(CF表!D$3="","",CF表!D11/10000) | E11: =IF(CF表!E$3="","",CF表!E11/10000) | F11: =IF(CF表!F$3="","",CF表!F11/10000) | G11: =IF(CF表!G$3="","",CF表!G11/10000) | H11: =IF(CF表!H$3="","",CF表!H11/10000) | I11: =IF(CF表!I$3="","",CF表!I11/10000) | ... CW11: =IF(CF表!CW$3="","",CF表!CW11/10000)
A12: 児童手当 | B12: =IF(CF表!B$3="","",CF表!B12/10000) | C12: =IF(CF表!C$3="","",CF表!C12/10000) | D12: =IF(CF表!D$3="","",CF表!D12/10000) | E12: =IF(CF表!E$3="","",CF表!E12/10000) | F12: =IF(CF表!F$3="","",CF表!F12/10000) | G12: =IF(CF表!G$3="","",CF表!G12/10000) | H12: =IF(CF表!H$3="","",CF表!H12/10000) | I12: =IF(CF表!I$3="","",CF表!I12/10000) | ... CW12: =IF(CF表!CW$3="","",CF表!CW12/10000)
A13: その他収入 | B13: =IF(CF表!B$3="","",CF表!B13/10000) | C13: =IF(CF表!C$3="","",CF表!C13/10000) | D13: =IF(CF表!D$3="","",CF表!D13/10000) | E13: =IF(CF表!E$3="","",CF表!E13/10000) | F13: =IF(CF表!F$3="","",CF表!F13/10000) | G13: =IF(CF表!G$3="","",CF表!G13/10000) | H13: =IF(CF表!H$3="","",CF表!H13/10000) | I13: =IF(CF表!I$3="","",CF表!I13/10000) | ... CW13: =IF(CF表!CW$3="","",CF表!CW13/10000)
A14: ご主人様退職金 | B14: =IF(CF表!B$3="","",CF表!B14/10000) | C14: =IF(CF表!C$3="","",CF表!C14/10000) | D14: =IF(CF表!D$3="","",CF表!D14/10000) | E14: =IF(CF表!E$3="","",CF表!E14/10000) | F14: =IF(CF表!F$3="","",CF表!F14/10000) | G14: =IF(CF表!G$3="","",CF表!G14/10000) | H14: =IF(CF表!H$3="","",CF表!H14/10000) | I14: =IF(CF表!I$3="","",CF表!I14/10000) | ... CW14: =IF(CF表!CW$3="","",CF表!CW14/10000)
A15: 奥様退職金 | B15: =IF(CF表!B$3="","",CF表!B15/10000) | C15: =IF(CF表!C$3="","",CF表!C15/10000) | D15: =IF(CF表!D$3="","",CF表!D15/10000) | E15: =IF(CF表!E$3="","",CF表!E15/10000) | F15: =IF(CF表!F$3="","",CF表!F15/10000) | G15: =IF(CF表!G$3="","",CF表!G15/10000) | H15: =IF(CF表!H$3="","",CF表!H15/10000) | I15: =IF(CF表!I$3="","",CF表!I15/10000) | ... CW15: =IF(CF表!CW$3="","",CF表!CW15/10000)
A16: ご主人様年金収入 | B16: =IF(CF表!B$3="","",CF表!B16/10000) | C16: =IF(CF表!C$3="","",CF表!C16/10000) | D16: =IF(CF表!D$3="","",CF表!D16/10000) | E16: =IF(CF表!E$3="","",CF表!E16/10000) | F16: =IF(CF表!F$3="","",CF表!F16/10000) | G16: =IF(CF表!G$3="","",CF表!G16/10000) | H16: =IF(CF表!H$3="","",CF表!H16/10000) | I16: =IF(CF表!I$3="","",CF表!I16/10000) | ... CW16: =IF(CF表!CW$3="","",CF表!CW16/10000)
A17: 奥様年金収入 | B17: =IF(CF表!B$3="","",CF表!B17/10000) | C17: =IF(CF表!C$3="","",CF表!C17/10000) | D17: =IF(CF表!D$3="","",CF表!D17/10000) | E17: =IF(CF表!E$3="","",CF表!E17/10000) | F17: =IF(CF表!F$3="","",CF表!F17/10000) | G17: =IF(CF表!G$3="","",CF表!G17/10000) | H17: =IF(CF表!H$3="","",CF表!H17/10000) | I17: =IF(CF表!I$3="","",CF表!I17/10000) | ... CW17: =IF(CF表!CW$3="","",CF表!CW17/10000)
A18: 世帯収入合計 | B18: =IF(CF表!B$3="","",CF表!B18/10000) | C18: =IF(CF表!C$3="","",CF表!C18/10000) | D18: =IF(CF表!D$3="","",CF表!D18/10000) | E18: =IF(CF表!E$3="","",CF表!E18/10000) | F18: =IF(CF表!F$3="","",CF表!F18/10000) | G18: =IF(CF表!G$3="","",CF表!G18/10000) | H18: =IF(CF表!H$3="","",CF表!H18/10000) | I18: =IF(CF表!I$3="","",CF表!I18/10000) | ... CW18: =IF(CF表!CW$3="","",CF表!CW18/10000)
A19: 収入
A20: 基本生活費 | B20: =IF(CF表!B$3="","",CF表!B20/10000) | C20: =IF(CF表!C$3="","",CF表!C20/10000) | D20: =IF(CF表!D$3="","",CF表!D20/10000) | E20: =IF(CF表!E$3="","",CF表!E20/10000) | F20: =IF(CF表!F$3="","",CF表!F20/10000) | G20: =IF(CF表!G$3="","",CF表!G20/10000) | H20: =IF(CF表!H$3="","",CF表!H20/10000) | I20: =IF(CF表!I$3="","",CF表!I20/10000) | ... CW20: =IF(CF表!CW$3="","",CF表!CW20/10000)
A21: 住居費 | B21: =IF(CF表!B$3="","",CF表!B21/10000) | C21: =IF(CF表!C$3="","",CF表!C21/10000) | D21: =IF(CF表!D$3="","",CF表!D21/10000) | E21: =IF(CF表!E$3="","",CF表!E21/10000) | F21: =IF(CF表!F$3="","",CF表!F21/10000) | G21: =IF(CF表!G$3="","",CF表!G21/10000) | H21: =IF(CF表!H$3="","",CF表!H21/10000) | I21: =IF(CF表!I$3="","",CF表!I21/10000) | ... CW21: =IF(CF表!CW$3="","",CF表!CW21/10000)
A22: 終身系保険料 | B22: =IF(CF表!B$3="","",CF表!B22/10000) | C22: =IF(CF表!C$3="","",CF表!C22/10000) | D22: =IF(CF表!D$3="","",CF表!D22/10000) | E22: =IF(CF表!E$3="","",CF表!E22/10000) | F22: =IF(CF表!F$3="","",CF表!F22/10000) | G22: =IF(CF表!G$3="","",CF表!G22/10000) | H22: =IF(CF表!H$3="","",CF表!H22/10000) | I22: =IF(CF表!I$3="","",CF表!I22/10000) | ... CW22: =IF(CF表!CW$3="","",CF表!CW22/10000)
A23: 定期系保険料 | B23: =IF(CF表!B$3="","",CF表!B23/10000) | C23: =IF(CF表!C$3="","",CF表!C23/10000) | D23: =IF(CF表!D$3="","",CF表!D23/10000) | E23: =IF(CF表!E$3="","",CF表!E23/10000) | F23: =IF(CF表!F$3="","",CF表!F23/10000) | G23: =IF(CF表!G$3="","",CF表!G23/10000) | H23: =IF(CF表!H$3="","",CF表!H23/10000) | I23: =IF(CF表!I$3="","",CF表!I23/10000) | ... CW23: =IF(CF表!CW$3="","",CF表!CW23/10000)
A24: 教育費 | B24: =IF(CF表!B$3="","",CF表!B24/10000) | C24: =IF(CF表!C$3="","",CF表!C24/10000) | D24: =IF(CF表!D$3="","",CF表!D24/10000) | E24: =IF(CF表!E$3="","",CF表!E24/10000) | F24: =IF(CF表!F$3="","",CF表!F24/10000) | G24: =IF(CF表!G$3="","",CF表!G24/10000) | H24: =IF(CF表!H$3="","",CF表!H24/10000) | I24: =IF(CF表!I$3="","",CF表!I24/10000) | ... CW24: =IF(CF表!CW$3="","",CF表!CW24/10000)
A25: 車関連費 | B25: =IF(CF表!B$3="","",CF表!B25/10000) | C25: =IF(CF表!C$3="","",CF表!C25/10000) | D25: =IF(CF表!D$3="","",CF表!D25/10000) | E25: =IF(CF表!E$3="","",CF表!E25/10000) | F25: =IF(CF表!F$3="","",CF表!F25/10000) | G25: =IF(CF表!G$3="","",CF表!G25/10000) | H25: =IF(CF表!H$3="","",CF表!H25/10000) | I25: =IF(CF表!I$3="","",CF表!I25/10000) | ... CW25: =IF(CF表!CW$3="","",CF表!CW25/10000)
A26: その他支出 | B26: =IF(CF表!B$3="","",CF表!B26/10000) | C26: =IF(CF表!C$3="","",CF表!C26/10000) | D26: =IF(CF表!D$3="","",CF表!D26/10000) | E26: =IF(CF表!E$3="","",CF表!E26/10000) | F26: =IF(CF表!F$3="","",CF表!F26/10000) | G26: =IF(CF表!G$3="","",CF表!G26/10000) | H26: =IF(CF表!H$3="","",CF表!H26/10000) | I26: =IF(CF表!I$3="","",CF表!I26/10000) | ... CW26: =IF(CF表!CW$3="","",CF表!CW26/10000)
A27: 一時支出 | B27: =IF(CF表!B$3="","",CF表!B27/10000) | C27: =IF(CF表!C$3="","",CF表!C27/10000) | D27: =IF(CF表!D$3="","",CF表!D27/10000) | E27: =IF(CF表!E$3="","",CF表!E27/10000) | F27: =IF(CF表!F$3="","",CF表!F27/10000) | G27: =IF(CF表!G$3="","",CF表!G27/10000) | H27: =IF(CF表!H$3="","",CF表!H27/10000) | I27: =IF(CF表!I$3="","",CF表!I27/10000) | ... CW27: =IF(CF表!CW$3="","",CF表!CW27/10000)
A28: 支出合計 | B28: =IF(CF表!B$3="","",CF表!B28/10000) | C28: =IF(CF表!C$3="","",CF表!C28/10000) | D28: =IF(CF表!D$3="","",CF表!D28/10000) | E28: =IF(CF表!E$3="","",CF表!E28/10000) | F28: =IF(CF表!F$3="","",CF表!F28/10000) | G28: =IF(CF表!G$3="","",CF表!G28/10000) | H28: =IF(CF表!H$3="","",CF表!H28/10000) | I28: =IF(CF表!I$3="","",CF表!I28/10000) | ... CW28: =IF(CF表!CW$3="","",CF表!CW28/10000)
A29: 収支・資産 | B29: =IF(CF表!B$3="","",CF表!B29/10000) | C29: =IF(CF表!C$3="","",CF表!C29/10000) | D29: =IF(CF表!D$3="","",CF表!D29/10000) | E29: =IF(CF表!E$3="","",CF表!E29/10000) | F29: =IF(CF表!F$3="","",CF表!F29/10000) | G29: =IF(CF表!G$3="","",CF表!G29/10000) | H29: =IF(CF表!H$3="","",CF表!H29/10000) | I29: =IF(CF表!I$3="","",CF表!I29/10000) | ... CW29: =IF(CF表!CW$3="","",CF表!CW29/10000)
A30: 年間収支 | B30: =IF(CF表!B$3="","",CF表!B30/10000) | C30: =IF(CF表!C$3="","",CF表!C30/10000) | D30: =IF(CF表!D$3="","",CF表!D30/10000) | E30: =IF(CF表!E$3="","",CF表!E30/10000) | F30: =IF(CF表!F$3="","",CF表!F30/10000) | G30: =IF(CF表!G$3="","",CF表!G30/10000) | H30: =IF(CF表!H$3="","",CF表!H30/10000) | I30: =IF(CF表!I$3="","",CF表!I30/10000) | ... CW30: =IF(CF表!CW$3="","",CF表!CW30/10000)
A31: 預貯金残高 | B31: =IF(CF表!B$3="","",CF表!B31/10000) | C31: =IF(CF表!C$3="","",CF表!C31/10000) | D31: =IF(CF表!D$3="","",CF表!D31/10000) | E31: =IF(CF表!E$3="","",CF表!E31/10000) | F31: =IF(CF表!F$3="","",CF表!F31/10000) | G31: =IF(CF表!G$3="","",CF表!G31/10000) | H31: =IF(CF表!H$3="","",CF表!H31/10000) | I31: =IF(CF表!I$3="","",CF表!I31/10000) | ... CW31: =IF(CF表!CW$3="","",CF表!CW31/10000)
... A45: 負債合計（参考） | B45: =IF(CF表!B$3="","",CF表!B45/10000) | C45: =IF(CF表!C$3="","",CF表!C45/10000) | D45: =IF(CF表!D$3="","",CF表!D45/10000) | E45: =IF(CF表!E$3="","",CF表!E45/10000) | F45: =IF(CF表!F$3="","",CF表!F45/10000) | G45: =IF(CF表!G$3="","",CF表!G45/10000) | H45: =IF(CF表!H$3="","",CF表!H45/10000) | I45: =IF(CF表!I$3="","",CF表!I45/10000) | ... CW45: =IF(CF表!CW$3="","",CF表!CW45/10000)

Sheet CF表（ご主人様死亡時・万円表示）
A1: CF表（ご主人様死亡時・万円表示）
A2: 試算終了年 | B2: ='CF表（ご主人様死亡時）'!B2
A3: 年 | B3: =IF('CF表（ご主人様死亡時）'!B3="","",'CF表（ご主人様死亡時）'!B3) | C3: =IF('CF表（ご主人様死亡時）'!C3="","",'CF表（ご主人様死亡時）'!C3) | D3: =IF('CF表（ご主人様死亡時）'!D3="","",'CF表（ご主人様死亡時）'!D3) | E3: =IF('CF表（ご主人様死亡時）'!E3="","",'CF表（ご主人様死亡時）'!E3) | F3: =IF('CF表（ご主人様死亡時）'!F3="","",'CF表（ご主人様死亡時）'!F3) | G3: =IF('CF表（ご主人様死亡時）'!G3="","",'CF表（ご主人様死亡時）'!G3) | H3: =IF('CF表（ご主人様死亡時）'!H3="","",'CF表（ご主人様死亡時）'!H3) | I3: =IF('CF表（ご主人様死亡時）'!I3="","",'CF表（ご主人様死亡時）'!I3) | ... CW3: =IF('CF表（ご主人様死亡時）'!CW3="","",'CF表（ご主人様死亡時）'!CW3)
A4: ご主人様年齢 | B4: =IF('CF表（ご主人様死亡時）'!B4="","",'CF表（ご主人様死亡時）'!B4) | C4: =IF('CF表（ご主人様死亡時）'!C4="","",'CF表（ご主人様死亡時）'!C4) | D4: =IF('CF表（ご主人様死亡時）'!D4="","",'CF表（ご主人様死亡時）'!D4) | E4: =IF('CF表（ご主人様死亡時）'!E4="","",'CF表（ご主人様死亡時）'!E4) | F4: =IF('CF表（ご主人様死亡時）'!F4="","",'CF表（ご主人様死亡時）'!F4) | G4: =IF('CF表（ご主人様死亡時）'!G4="","",'CF表（ご主人様死亡時）'!G4) | H4: =IF('CF表（ご主人様死亡時）'!H4="","",'CF表（ご主人様死亡時）'!H4) | I4: =IF('CF表（ご主人様死亡時）'!I4="","",'CF表（ご主人様死亡時）'!I4) | ... CW4: =IF('CF表（ご主人様死亡時）'!CW4="","",'CF表（ご主人様死亡時）'!CW4)
A5: 奥様年齢 | B5: =IF('CF表（ご主人様死亡時）'!B5="","",'CF表（ご主人様死亡時）'!B5) | C5: =IF('CF表（ご主人様死亡時）'!C5="","",'CF表（ご主人様死亡時）'!C5) | D5: =IF('CF表（ご主人様死亡時）'!D5="","",'CF表（ご主人様死亡時）'!D5) | E5: =IF('CF表（ご主人様死亡時）'!E5="","",'CF表（ご主人様死亡時）'!E5) | F5: =IF('CF表（ご主人様死亡時）'!F5="","",'CF表（ご主人様死亡時）'!F5) | G5: =IF('CF表（ご主人様死亡時）'!G5="","",'CF表（ご主人様死亡時）'!G5) | H5: =IF('CF表（ご主人様死亡時）'!H5="","",'CF表（ご主人様死亡時）'!H5) | I5: =IF('CF表（ご主人様死亡時）'!I5="","",'CF表（ご主人様死亡時）'!I5) | ... CW5: =IF('CF表（ご主人様死亡時）'!CW5="","",'CF表（ご主人様死亡時）'!CW5)
A6: 子1年齢 | B6: =IF('CF表（ご主人様死亡時）'!B6="","",'CF表（ご主人様死亡時）'!B6) | C6: =IF('CF表（ご主人様死亡時）'!C6="","",'CF表（ご主人様死亡時）'!C6) | D6: =IF('CF表（ご主人様死亡時）'!D6="","",'CF表（ご主人様死亡時）'!D6) | E6: =IF('CF表（ご主人様死亡時）'!E6="","",'CF表（ご主人様死亡時）'!E6) | F6: =IF('CF表（ご主人様死亡時）'!F6="","",'CF表（ご主人様死亡時）'!F6) | G6: =IF('CF表（ご主人様死亡時）'!G6="","",'CF表（ご主人様死亡時）'!G6) | H6: =IF('CF表（ご主人様死亡時）'!H6="","",'CF表（ご主人様死亡時）'!H6) | I6: =IF('CF表（ご主人様死亡時）'!I6="","",'CF表（ご主人様死亡時）'!I6) | ... CW6: =IF('CF表（ご主人様死亡時）'!CW6="","",'CF表（ご主人様死亡時）'!CW6)
A7: 子2年齢 | B7: =IF('CF表（ご主人様死亡時）'!B7="","",'CF表（ご主人様死亡時）'!B7) | C7: =IF('CF表（ご主人様死亡時）'!C7="","",'CF表（ご主人様死亡時）'!C7) | D7: =IF('CF表（ご主人様死亡時）'!D7="","",'CF表（ご主人様死亡時）'!D7) | E7: =IF('CF表（ご主人様死亡時）'!E7="","",'CF表（ご主人様死亡時）'!E7) | F7: =IF('CF表（ご主人様死亡時）'!F7="","",'CF表（ご主人様死亡時）'!F7) | G7: =IF('CF表（ご主人様死亡時）'!G7="","",'CF表（ご主人様死亡時）'!G7) | H7: =IF('CF表（ご主人様死亡時）'!H7="","",'CF表（ご主人様死亡時）'!H7) | I7: =IF('CF表（ご主人様死亡時）'!I7="","",'CF表（ご主人様死亡時）'!I7) | ... CW7: =IF('CF表（ご主人様死亡時）'!CW7="","",'CF表（ご主人様死亡時）'!CW7)
A8: 子3年齢 | B8: =IF('CF表（ご主人様死亡時）'!B8="","",'CF表（ご主人様死亡時）'!B8) | C8: =IF('CF表（ご主人様死亡時）'!C8="","",'CF表（ご主人様死亡時）'!C8) | D8: =IF('CF表（ご主人様死亡時）'!D8="","",'CF表（ご主人様死亡時）'!D8) | E8: =IF('CF表（ご主人様死亡時）'!E8="","",'CF表（ご主人様死亡時）'!E8) | F8: =IF('CF表（ご主人様死亡時）'!F8="","",'CF表（ご主人様死亡時）'!F8) | G8: =IF('CF表（ご主人様死亡時）'!G8="","",'CF表（ご主人様死亡時）'!G8) | H8: =IF('CF表（ご主人様死亡時）'!H8="","",'CF表（ご主人様死亡時）'!H8) | I8: =IF('CF表（ご主人様死亡時）'!I8="","",'CF表（ご主人様死亡時）'!I8) | ... CW8: =IF('CF表（ご主人様死亡時）'!CW8="","",'CF表（ご主人様死亡時）'!CW8)
A9: 家族年齢
A10: ご主人様収入 | B10: =IF('CF表（ご主人様死亡時）'!B$3="","",'CF表（ご主人様死亡時）'!B10/10000) | C10: =IF('CF表（ご主人様死亡時）'!C$3="","",'CF表（ご主人様死亡時）'!C10/10000) | D10: =IF('CF表（ご主人様死亡時）'!D$3="","",'CF表（ご主人様死亡時）'!D10/10000) | E10: =IF('CF表（ご主人様死亡時）'!E$3="","",'CF表（ご主人様死亡時）'!E10/10000) | F10: =IF('CF表（ご主人様死亡時）'!F$3="","",'CF表（ご主人様死亡時）'!F10/10000) | G10: =IF('CF表（ご主人様死亡時）'!G$3="","",'CF表（ご主人様死亡時）'!G10/10000) | H10: =IF('CF表（ご主人様死亡時）'!H$3="","",'CF表（ご主人様死亡時）'!H10/10000) | I10: =IF('CF表（ご主人様死亡時）'!I$3="","",'CF表（ご主人様死亡時）'!I10/10000) | ... CW10: =IF('CF表（ご主人様死亡時）'!CW$3="","",'CF表（ご主人様死亡時）'!CW10/10000)
A11: 奥様収入 | B11: =IF('CF表（ご主人様死亡時）'!B$3="","",'CF表（ご主人様死亡時）'!B11/10000) | C11: =IF('CF表（ご主人様死亡時）'!C$3="","",'CF表（ご主人様死亡時）'!C11/10000) | D11: =IF('CF表（ご主人様死亡時）'!D$3="","",'CF表（ご主人様死亡時）'!D11/10000) | E11: =IF('CF表（ご主人様死亡時）'!E$3="","",'CF表（ご主人様死亡時）'!E11/10000) | F11: =IF('CF表（ご主人様死亡時）'!F$3="","",'CF表（ご主人様死亡時）'!F11/10000) | G11: =IF('CF表（ご主人様死亡時）'!G$3="","",'CF表（ご主人様死亡時）'!G11/10000) | H11: =IF('CF表（ご主人様死亡時）'!H$3="","",'CF表（ご主人様死亡時）'!H11/10000) | I11: =IF('CF表（ご主人様死亡時）'!I$3="","",'CF表（ご主人様死亡時）'!I11/10000) | ... CW11: =IF('CF表（ご主人様死亡時）'!CW$3="","",'CF表（ご主人様死亡時）'!CW11/10000)
A12: 児童手当 | B12: =IF('CF表（ご主人様死亡時）'!B$3="","",'CF表（ご主人様死亡時）'!B12/10000) | C12: =IF('CF表（ご主人様死亡時）'!C$3="","",'CF表（ご主人様死亡時）'!C12/10000) | D12: =IF('CF表（ご主人様死亡時）'!D$3="","",'CF表（ご主人様死亡時）'!D12/10000) | E12: =IF('CF表（ご主人様死亡時）'!E$3="","",'CF表（ご主人様死亡時）'!E12/10000) | F12: =IF('CF表（ご主人様死亡時）'!F$3="","",'CF表（ご主人様死亡時）'!F12/10000) | G12: =IF('CF表（ご主人様死亡時）'!G$3="","",'CF表（ご主人様死亡時）'!G12/10000) | H12: =IF('CF表（ご主人様死亡時）'!H$3="","",'CF表（ご主人様死亡時）'!H12/10000) | I12: =IF('CF表（ご主人様死亡時）'!I$3="","",'CF表（ご主人様死亡時）'!I12/10000) | ... CW12: =IF('CF表（ご主人様死亡時）'!CW$3="","",'CF表（ご主人様死亡時）'!CW12/10000)
A13: その他収入 | B13: =IF('CF表（ご主人様死亡時）'!B$3="","",'CF表（ご主人様死亡時）'!B13/10000) | C13: =IF('CF表（ご主人様死亡時）'!C$3="","",'CF表（ご主人様死亡時）'!C13/10000) | D13: =IF('CF表（ご主人様死亡時）'!D$3="","",'CF表（ご主人様死亡時）'!D13/10000) | E13: =IF('CF表（ご主人様死亡時）'!E$3="","",'CF表（ご主人様死亡時）'!E13/10000) | F13: =IF('CF表（ご主人様死亡時）'!F$3="","",'CF表（ご主人様死亡時）'!F13/10000) | G13: =IF('CF表（ご主人様死亡時）'!G$3="","",'CF表（ご主人様死亡時）'!G13/10000) | H13: =IF('CF表（ご主人様死亡時）'!H$3="","",'CF表（ご主人様死亡時）'!H13/10000) | I13: =IF('CF表（ご主人様死亡時）'!I$3="","",'CF表（ご主人様死亡時）'!I13/10000) | ... CW13: =IF('CF表（ご主人様死亡時）'!CW$3="","",'CF表（ご主人様死亡時）'!CW13/10000)
A14: ご主人様退職金 | B14: =IF('CF表（ご主人様死亡時）'!B$3="","",'CF表（ご主人様死亡時）'!B14/10000) | C14: =IF('CF表（ご主人様死亡時）'!C$3="","",'CF表（ご主人様死亡時）'!C14/10000) | D14: =IF('CF表（ご主人様死亡時）'!D$3="","",'CF表（ご主人様死亡時）'!D14/10000) | E14: =IF('CF表（ご主人様死亡時）'!E$3="","",'CF表（ご主人様死亡時）'!E14/10000) | F14: =IF('CF表（ご主人様死亡時）'!F$3="","",'CF表（ご主人様死亡時）'!F14/10000) | G14: =IF('CF表（ご主人様死亡時）'!G$3="","",'CF表（ご主人様死亡時）'!G14/10000) | H14: =IF('CF表（ご主人様死亡時）'!H$3="","",'CF表（ご主人様死亡時）'!H14/10000) | I14: =IF('CF表（ご主人様死亡時）'!I$3="","",'CF表（ご主人様死亡時）'!I14/10000) | ... CW14: =IF('CF表（ご主人様死亡時）'!CW$3="","",'CF表（ご主人様死亡時）'!CW14/10000)
A15: 奥様退職金 | B15: =IF('CF表（ご主人様死亡時）'!B$3="","",'CF表（ご主人様死亡時）'!B15/10000) | C15: =IF('CF表（ご主人様死亡時）'!C$3="","",'CF表（ご主人様死亡時）'!C15/10000) | D15: =IF('CF表（ご主人様死亡時）'!D$3="","",'CF表（ご主人様死亡時）'!D15/10000) | E15: =IF('CF表（ご主人様死亡時）'!E$3="","",'CF表（ご主人様死亡時）'!E15/10000) | F15: =IF('CF表（ご主人様死亡時）'!F$3="","",'CF表（ご主人様死亡時）'!F15/10000) | G15: =IF('CF表（ご主人様死亡時）'!G$3="","",'CF表（ご主人様死亡時）'!G15/10000) | H15: =IF('CF表（ご主人様死亡時）'!H$3="","",'CF表（ご主人様死亡時）'!H15/10000) | I15: =IF('CF表（ご主人様死亡時）'!I$3="","",'CF表（ご主人様死亡時）'!I15/10000) | ... CW15: =IF('CF表（ご主人様死亡時）'!CW$3="","",'CF表（ご主人様死亡時）'!CW15/10000)
A16: ご主人様年金収入 | B16: =IF('CF表（ご主人様死亡時）'!B$3="","",'CF表（ご主人様死亡時）'!B16/10000) | C16: =IF('CF表（ご主人様死亡時）'!C$3="","",'CF表（ご主人様死亡時）'!C16/10000) | D16: =IF('CF表（ご主人様死亡時）'!D$3="","",'CF表（ご主人様死亡時）'!D16/10000) | E16: =IF('CF表（ご主人様死亡時）'!E$3="","",'CF表（ご主人様死亡時）'!E16/10000) | F16: =IF('CF表（ご主人様死亡時）'!F$3="","",'CF表（ご主人様死亡時）'!F16/10000) | G16: =IF('CF表（ご主人様死亡時）'!G$3="","",'CF表（ご主人様死亡時）'!G16/10000) | H16: =IF('CF表（ご主人様死亡時）'!H$3="","",'CF表（ご主人様死亡時）'!H16/10000) | I16: =IF('CF表（ご主人様死亡時）'!I$3="","",'CF表（ご主人様死亡時）'!I16/10000) | ... CW16: =IF('CF表（ご主人様死亡時）'!CW$3="","",'CF表（ご主人様死亡時）'!CW16/10000)
A17: 奥様年金収入 | B17: =IF('CF表（ご主人様死亡時）'!B$3="","",'CF表（ご主人様死亡時）'!B17/10000) | C17: =IF('CF表（ご主人様死亡時）'!C$3="","",'CF表（ご主人様死亡時）'!C17/10000) | D17: =IF('CF表（ご主人様死亡時）'!D$3="","",'CF表（ご主人様死亡時）'!D17/10000) | E17: =IF('CF表（ご主人様死亡時）'!E$3="","",'CF表（ご主人様死亡時）'!E17/10000) | F17: =IF('CF表（ご主人様死亡時）'!F$3="","",'CF表（ご主人様死亡時）'!F17/10000) | G17: =IF('CF表（ご主人様死亡時）'!G$3="","",'CF表（ご主人様死亡時）'!G17/10000) | H17: =IF('CF表（ご主人様死亡時）'!H$3="","",'CF表（ご主人様死亡時）'!H17/10000) | I17: =IF('CF表（ご主人様死亡時）'!I$3="","",'CF表（ご主人様死亡時）'!I17/10000) | ... CW17: =IF('CF表（ご主人様死亡時）'!CW$3="","",'CF表（ご主人様死亡時）'!CW17/10000)
A18: 世帯収入合計 | B18: =IF('CF表（ご主人様死亡時）'!B$3="","",'CF表（ご主人様死亡時）'!B18/10000) | C18: =IF('CF表（ご主人様死亡時）'!C$3="","",'CF表（ご主人様死亡時）'!C18/10000) | D18: =IF('CF表（ご主人様死亡時）'!D$3="","",'CF表（ご主人様死亡時）'!D18/10000) | E18: =IF('CF表（ご主人様死亡時）'!E$3="","",'CF表（ご主人様死亡時）'!E18/10000) | F18: =IF('CF表（ご主人様死亡時）'!F$3="","",'CF表（ご主人様死亡時）'!F18/10000) | G18: =IF('CF表（ご主人様死亡時）'!G$3="","",'CF表（ご主人様死亡時）'!G18/10000) | H18: =IF('CF表（ご主人様死亡時）'!H$3="","",'CF表（ご主人様死亡時）'!H18/10000) | I18: =IF('CF表（ご主人様死亡時）'!I$3="","",'CF表（ご主人様死亡時）'!I18/10000) | ... CW18: =IF('CF表（ご主人様死亡時）'!CW$3="","",'CF表（ご主人様死亡時）'!CW18/10000)
A19: 収入
A20: 基本生活費 | B20: =IF('CF表（ご主人様死亡時）'!B$3="","",'CF表（ご主人様死亡時）'!B20/10000) | C20: =IF('CF表（ご主人様死亡時）'!C$3="","",'CF表（ご主人様死亡時）'!C20/10000) | D20: =IF('CF表（ご主人様死亡時）'!D$3="","",'CF表（ご主人様死亡時）'!D20/10000) | E20: =IF('CF表（ご主人様死亡時）'!E$3="","",'CF表（ご主人様死亡時）'!E20/10000) | F20: =IF('CF表（ご主人様死亡時）'!F$3="","",'CF表（ご主人様死亡時）'!F20/10000) | G20: =IF('CF表（ご主人様死亡時）'!G$3="","",'CF表（ご主人様死亡時）'!G20/10000) | H20: =IF('CF表（ご主人様死亡時）'!H$3="","",'CF表（ご主人様死亡時）'!H20/10000) | I20: =IF('CF表（ご主人様死亡時）'!I$3="","",'CF表（ご主人様死亡時）'!I20/10000) | ... CW20: =IF('CF表（ご主人様死亡時）'!CW$3="","",'CF表（ご主人様死亡時）'!CW20/10000)
A21: 住居費 | B21: =IF('CF表（ご主人様死亡時）'!B$3="","",'CF表（ご主人様死亡時）'!B21/10000) | C21: =IF('CF表（ご主人様死亡時）'!C$3="","",'CF表（ご主人様死亡時）'!C21/10000) | D21: =IF('CF表（ご主人様死亡時）'!D$3="","",'CF表（ご主人様死亡時）'!D21/10000) | E21: =IF('CF表（ご主人様死亡時）'!E$3="","",'CF表（ご主人様死亡時）'!E21/10000) | F21: =IF('CF表（ご主人様死亡時）'!F$3="","",'CF表（ご主人様死亡時）'!F21/10000) | G21: =IF('CF表（ご主人様死亡時）'!G$3="","",'CF表（ご主人様死亡時）'!G21/10000) | H21: =IF('CF表（ご主人様死亡時）'!H$3="","",'CF表（ご主人様死亡時）'!H21/10000) | I21: =IF('CF表（ご主人様死亡時）'!I$3="","",'CF表（ご主人様死亡時）'!I21/10000) | ... CW21: =IF('CF表（ご主人様死亡時）'!CW$3="","",'CF表（ご主人様死亡時）'!CW21/10000)
A22: 終身系保険料 | B22: =IF('CF表（ご主人様死亡時）'!B$3="","",'CF表（ご主人様死亡時）'!B22/10000) | C22: =IF('CF表（ご主人様死亡時）'!C$3="","",'CF表（ご主人様死亡時）'!C22/10000) | D22: =IF('CF表（ご主人様死亡時）'!D$3="","",'CF表（ご主人様死亡時）'!D22/10000) | E22: =IF('CF表（ご主人様死亡時）'!E$3="","",'CF表（ご主人様死亡時）'!E22/10000) | F22: =IF('CF表（ご主人様死亡時）'!F$3="","",'CF表（ご主人様死亡時）'!F22/10000) | G22: =IF('CF表（ご主人様死亡時）'!G$3="","",'CF表（ご主人様死亡時）'!G22/10000) | H22: =IF('CF表（ご主人様死亡時）'!H$3="","",'CF表（ご主人様死亡時）'!H22/10000) | I22: =IF('CF表（ご主人様死亡時）'!I$3="","",'CF表（ご主人様死亡時）'!I22/10000) | ... CW22: =IF('CF表（ご主人様死亡時）'!CW$3="","",'CF表（ご主人様死亡時）'!CW22/10000)
A23: 定期系保険料 | B23: =IF('CF表（ご主人様死亡時）'!B$3="","",'CF表（ご主人様死亡時）'!B23/10000) | C23: =IF('CF表（ご主人様死亡時）'!C$3="","",'CF表（ご主人様死亡時）'!C23/10000) | D23: =IF('CF表（ご主人様死亡時）'!D$3="","",'CF表（ご主人様死亡時）'!D23/10000) | E23: =IF('CF表（ご主人様死亡時）'!E$3="","",'CF表（ご主人様死亡時）'!E23/10000) | F23: =IF('CF表（ご主人様死亡時）'!F$3="","",'CF表（ご主人様死亡時）'!F23/10000) | G23: =IF('CF表（ご主人様死亡時）'!G$3="","",'CF表（ご主人様死亡時）'!G23/10000) | H23: =IF('CF表（ご主人様死亡時）'!H$3="","",'CF表（ご主人様死亡時）'!H23/10000) | I23: =IF('CF表（ご主人様死亡時）'!I$3="","",'CF表（ご主人様死亡時）'!I23/10000) | ... CW23: =IF('CF表（ご主人様死亡時）'!CW$3="","",'CF表（ご主人様死亡時）'!CW23/10000)
A24: 教育費 | B24: =IF('CF表（ご主人様死亡時）'!B$3="","",'CF表（ご主人様死亡時）'!B24/10000) | C24: =IF('CF表（ご主人様死亡時）'!C$3="","",'CF表（ご主人様死亡時）'!C24/10000) | D24: =IF('CF表（ご主人様死亡時）'!D$3="","",'CF表（ご主人様死亡時）'!D24/10000) | E24: =IF('CF表（ご主人様死亡時）'!E$3="","",'CF表（ご主人様死亡時）'!E24/10000) | F24: =IF('CF表（ご主人様死亡時）'!F$3="","",'CF表（ご主人様死亡時）'!F24/10000) | G24: =IF('CF表（ご主人様死亡時）'!G$3="","",'CF表（ご主人様死亡時）'!G24/10000) | H24: =IF('CF表（ご主人様死亡時）'!H$3="","",'CF表（ご主人様死亡時）'!H24/10000) | I24: =IF('CF表（ご主人様死亡時）'!I$3="","",'CF表（ご主人様死亡時）'!I24/10000) | ... CW24: =IF('CF表（ご主人様死亡時）'!CW$3="","",'CF表（ご主人様死亡時）'!CW24/10000)
A25: 車関連費 | B25: =IF('CF表（ご主人様死亡時）'!B$3="","",'CF表（ご主人様死亡時）'!B25/10000) | C25: =IF('CF表（ご主人様死亡時）'!C$3="","",'CF表（ご主人様死亡時）'!C25/10000) | D25: =IF('CF表（ご主人様死亡時）'!D$3="","",'CF表（ご主人様死亡時）'!D25/10000) | E25: =IF('CF表（ご主人様死亡時）'!E$3="","",'CF表（ご主人様死亡時）'!E25/10000) | F25: =IF('CF表（ご主人様死亡時）'!F$3="","",'CF表（ご主人様死亡時）'!F25/10000) | G25: =IF('CF表（ご主人様死亡時）'!G$3="","",'CF表（ご主人様死亡時）'!G25/10000) | H25: =IF('CF表（ご主人様死亡時）'!H$3="","",'CF表（ご主人様死亡時）'!H25/10000) | I25: =IF('CF表（ご主人様死亡時）'!I$3="","",'CF表（ご主人様死亡時）'!I25/10000) | ... CW25: =IF('CF表（ご主人様死亡時）'!CW$3="","",'CF表（ご主人様死亡時）'!CW25/10000)
A26: その他支出 | B26: =IF('CF表（ご主人様死亡時）'!B$3="","",'CF表（ご主人様死亡時）'!B26/10000) | C26: =IF('CF表（ご主人様死亡時）'!C$3="","",'CF表（ご主人様死亡時）'!C26/10000) | D26: =IF('CF表（ご主人様死亡時）'!D$3="","",'CF表（ご主人様死亡時）'!D26/10000) | E26: =IF('CF表（ご主人様死亡時）'!E$3="","",'CF表（ご主人様死亡時）'!E26/10000) | F26: =IF('CF表（ご主人様死亡時）'!F$3="","",'CF表（ご主人様死亡時）'!F26/10000) | G26: =IF('CF表（ご主人様死亡時）'!G$3="","",'CF表（ご主人様死亡時）'!G26/10000) | H26: =IF('CF表（ご主人様死亡時）'!H$3="","",'CF表（ご主人様死亡時）'!H26/10000) | I26: =IF('CF表（ご主人様死亡時）'!I$3="","",'CF表（ご主人様死亡時）'!I26/10000) | ... CW26: =IF('CF表（ご主人様死亡時）'!CW$3="","",'CF表（ご主人様死亡時）'!CW26/10000)
A27: 一時支出 | B27: =IF('CF表（ご主人様死亡時）'!B$3="","",'CF表（ご主人様死亡時）'!B27/10000) | C27: =IF('CF表（ご主人様死亡時）'!C$3="","",'CF表（ご主人様死亡時）'!C27/10000) | D27: =IF('CF表（ご主人様死亡時）'!D$3="","",'CF表（ご主人様死亡時）'!D27/10000) | E27: =IF('CF表（ご主人様死亡時）'!E$3="","",'CF表（ご主人様死亡時）'!E27/10000) | F27: =IF('CF表（ご主人様死亡時）'!F$3="","",'CF表（ご主人様死亡時）'!F27/10000) | G27: =IF('CF表（ご主人様死亡時）'!G$3="","",'CF表（ご主人様死亡時）'!G27/10000) | H27: =IF('CF表（ご主人様死亡時）'!H$3="","",'CF表（ご主人様死亡時）'!H27/10000) | I27: =IF('CF表（ご主人様死亡時）'!I$3="","",'CF表（ご主人様死亡時）'!I27/10000) | ... CW27: =IF('CF表（ご主人様死亡時）'!CW$3="","",'CF表（ご主人様死亡時）'!CW27/10000)
A28: 支出合計 | B28: =IF('CF表（ご主人様死亡時）'!B$3="","",'CF表（ご主人様死亡時）'!B28/10000) | C28: =IF('CF表（ご主人様死亡時）'!C$3="","",'CF表（ご主人様死亡時）'!C28/10000) | D28: =IF('CF表（ご主人様死亡時）'!D$3="","",'CF表（ご主人様死亡時）'!D28/10000) | E28: =IF('CF表（ご主人様死亡時）'!E$3="","",'CF表（ご主人様死亡時）'!E28/10000) | F28: =IF('CF表（ご主人様死亡時）'!F$3="","",'CF表（ご主人様死亡時）'!F28/10000) | G28: =IF('CF表（ご主人様死亡時）'!G$3="","",'CF表（ご主人様死亡時）'!G28/10000) | H28: =IF('CF表（ご主人様死亡時）'!H$3="","",'CF表（ご主人様死亡時）'!H28/10000) | I28: =IF('CF表（ご主人様死亡時）'!I$3="","",'CF表（ご主人様死亡時）'!I28/10000) | ... CW28: =IF('CF表（ご主人様死亡時）'!CW$3="","",'CF表（ご主人様死亡時）'!CW28/10000)
A29: 収支・資産 | B29: =IF('CF表（ご主人様死亡時）'!B$3="","",'CF表（ご主人様死亡時）'!B29/10000) | C29: =IF('CF表（ご主人様死亡時）'!C$3="","",'CF表（ご主人様死亡時）'!C29/10000) | D29: =IF('CF表（ご主人様死亡時）'!D$3="","",'CF表（ご主人様死亡時）'!D29/10000) | E29: =IF('CF表（ご主人様死亡時）'!E$3="","",'CF表（ご主人様死亡時）'!E29/10000) | F29: =IF('CF表（ご主人様死亡時）'!F$3="","",'CF表（ご主人様死亡時）'!F29/10000) | G29: =IF('CF表（ご主人様死亡時）'!G$3="","",'CF表（ご主人様死亡時）'!G29/10000) | H29: =IF('CF表（ご主人様死亡時）'!H$3="","",'CF表（ご主人様死亡時）'!H29/10000) | I29: =IF('CF表（ご主人様死亡時）'!I$3="","",'CF表（ご主人様死亡時）'!I29/10000) | ... CW29: =IF('CF表（ご主人様死亡時）'!CW$3="","",'CF表（ご主人様死亡時）'!CW29/10000)
A30: 年間収支 | B30: =IF('CF表（ご主人様死亡時）'!B$3="","",'CF表（ご主人様死亡時）'!B30/10000) | C30: =IF('CF表（ご主人様死亡時）'!C$3="","",'CF表（ご主人様死亡時）'!C30/10000) | D30: =IF('CF表（ご主人様死亡時）'!D$3="","",'CF表（ご主人様死亡時）'!D30/10000) | E30: =IF('CF表（ご主人様死亡時）'!E$3="","",'CF表（ご主人様死亡時）'!E30/10000) | F30: =IF('CF表（ご主人様死亡時）'!F$3="","",'CF表（ご主人様死亡時）'!F30/10000) | G30: =IF('CF表（ご主人様死亡時）'!G$3="","",'CF表（ご主人様死亡時）'!G30/10000) | H30: =IF('CF表（ご主人様死亡時）'!H$3="","",'CF表（ご主人様死亡時）'!H30/10000) | I30: =IF('CF表（ご主人様死亡時）'!I$3="","",'CF表（ご主人様死亡時）'!I30/10000) | ... CW30: =IF('CF表（ご主人様死亡時）'!CW$3="","",'CF表（ご主人様死亡時）'!CW30/10000)
A31: 預貯金残高 | B31: =IF('CF表（ご主人様死亡時）'!B$3="","",'CF表（ご主人様死亡時）'!B31/10000) | C31: =IF('CF表（ご主人様死亡時）'!C$3="","",'CF表（ご主人様死亡時）'!C31/10000) | D31: =IF('CF表（ご主人様死亡時）'!D$3="","",'CF表（ご主人様死亡時）'!D31/10000) | E31: =IF('CF表（ご主人様死亡時）'!E$3="","",'CF表（ご主人様死亡時）'!E31/10000) | F31: =IF('CF表（ご主人様死亡時）'!F$3="","",'CF表（ご主人様死亡時）'!F31/10000) | G31: =IF('CF表（ご主人様死亡時）'!G$3="","",'CF表（ご主人様死亡時）'!G31/10000) | H31: =IF('CF表（ご主人様死亡時）'!H$3="","",'CF表（ご主人様死亡時）'!H31/10000) | I31: =IF('CF表（ご主人様死亡時）'!I$3="","",'CF表（ご主人様死亡時）'!I31/10000) | ... CW31: =IF('CF表（ご主人様死亡時）'!CW$3="","",'CF表（ご主人様死亡時）'!CW31/10000)
... A45: 負債合計（参考） | B45: =IF('CF表（ご主人様死亡時）'!B$3="","",'CF表（ご主人様死亡時）'!B45/10000) | C45: =IF('CF表（ご主人様死亡時）'!C$3="","",'CF表（ご主人様死亡時）'!C45/10000) | D45: =IF('CF表（ご主人様死亡時）'!D$3="","",'CF表（ご主人様死亡時）'!D45/10000) | E45: =IF('CF表（ご主人様死亡時）'!E$3="","",'CF表（ご主人様死亡時）'!E45/10000) | F45: =IF('CF表（ご主人様死亡時）'!F$3="","",'CF表（ご主人様死亡時）'!F45/10000) | G45: =IF('CF表（ご主人様死亡時）'!G$3="","",'CF表（ご主人様死亡時）'!G45/10000) | H45: =IF('CF表（ご主人様死亡時）'!H$3="","",'CF表（ご主人様死亡時）'!H45/10000) | I45: =IF('CF表（ご主人様死亡時）'!I$3="","",'CF表（ご主人様死亡時）'!I45/10000) | ... CW45: =IF('CF表（ご主人様死亡時）'!CW$3="","",'CF表（ご主人様死亡時）'!CW45/10000)

Sheet CF表（奥様死亡時・万円表示）
A1: CF表（奥様死亡時・万円表示）
A2: 試算終了年 | B2: ='CF表（奥様死亡時）'!B2
A3: 年 | B3: =IF('CF表（奥様死亡時）'!B3="","",'CF表（奥様死亡時）'!B3) | C3: =IF('CF表（奥様死亡時）'!C3="","",'CF表（奥様死亡時）'!C3) | D3: =IF('CF表（奥様死亡時）'!D3="","",'CF表（奥様死亡時）'!D3) | E3: =IF('CF表（奥様死亡時）'!E3="","",'CF表（奥様死亡時）'!E3) | F3: =IF('CF表（奥様死亡時）'!F3="","",'CF表（奥様死亡時）'!F3) | G3: =IF('CF表（奥様死亡時）'!G3="","",'CF表（奥様死亡時）'!G3) | H3: =IF('CF表（奥様死亡時）'!H3="","",'CF表（奥様死亡時）'!H3) | I3: =IF('CF表（奥様死亡時）'!I3="","",'CF表（奥様死亡時）'!I3) | ... CW3: =IF('CF表（奥様死亡時）'!CW3="","",'CF表（奥様死亡時）'!CW3)
A4: ご主人様年齢 | B4: =IF('CF表（奥様死亡時）'!B4="","",'CF表（奥様死亡時）'!B4) | C4: =IF('CF表（奥様死亡時）'!C4="","",'CF表（奥様死亡時）'!C4) | D4: =IF('CF表（奥様死亡時）'!D4="","",'CF表（奥様死亡時）'!D4) | E4: =IF('CF表（奥様死亡時）'!E4="","",'CF表（奥様死亡時）'!E4) | F4: =IF('CF表（奥様死亡時）'!F4="","",'CF表（奥様死亡時）'!F4) | G4: =IF('CF表（奥様死亡時）'!G4="","",'CF表（奥様死亡時）'!G4) | H4: =IF('CF表（奥様死亡時）'!H4="","",'CF表（奥様死亡時）'!H4) | I4: =IF('CF表（奥様死亡時）'!I4="","",'CF表（奥様死亡時）'!I4) | ... CW4: =IF('CF表（奥様死亡時）'!CW4="","",'CF表（奥様死亡時）'!CW4)
A5: 奥様年齢 | B5: =IF('CF表（奥様死亡時）'!B5="","",'CF表（奥様死亡時）'!B5) | C5: =IF('CF表（奥様死亡時）'!C5="","",'CF表（奥様死亡時）'!C5) | D5: =IF('CF表（奥様死亡時）'!D5="","",'CF表（奥様死亡時）'!D5) | E5: =IF('CF表（奥様死亡時）'!E5="","",'CF表（奥様死亡時）'!E5) | F5: =IF('CF表（奥様死亡時）'!F5="","",'CF表（奥様死亡時）'!F5) | G5: =IF('CF表（奥様死亡時）'!G5="","",'CF表（奥様死亡時）'!G5) | H5: =IF('CF表（奥様死亡時）'!H5="","",'CF表（奥様死亡時）'!H5) | I5: =IF('CF表（奥様死亡時）'!I5="","",'CF表（奥様死亡時）'!I5) | ... CW5: =IF('CF表（奥様死亡時）'!CW5="","",'CF表（奥様死亡時）'!CW5)
A6: 子1年齢 | B6: =IF('CF表（奥様死亡時）'!B6="","",'CF表（奥様死亡時）'!B6) | C6: =IF('CF表（奥様死亡時）'!C6="","",'CF表（奥様死亡時）'!C6) | D6: =IF('CF表（奥様死亡時）'!D6="","",'CF表（奥様死亡時）'!D6) | E6: =IF('CF表（奥様死亡時）'!E6="","",'CF表（奥様死亡時）'!E6) | F6: =IF('CF表（奥様死亡時）'!F6="","",'CF表（奥様死亡時）'!F6) | G6: =IF('CF表（奥様死亡時）'!G6="","",'CF表（奥様死亡時）'!G6) | H6: =IF('CF表（奥様死亡時）'!H6="","",'CF表（奥様死亡時）'!H6) | I6: =IF('CF表（奥様死亡時）'!I6="","",'CF表（奥様死亡時）'!I6) | ... CW6: =IF('CF表（奥様死亡時）'!CW6="","",'CF表（奥様死亡時）'!CW6)
A7: 子2年齢 | B7: =IF('CF表（奥様死亡時）'!B7="","",'CF表（奥様死亡時）'!B7) | C7: =IF('CF表（奥様死亡時）'!C7="","",'CF表（奥様死亡時）'!C7) | D7: =IF('CF表（奥様死亡時）'!D7="","",'CF表（奥様死亡時）'!D7) | E7: =IF('CF表（奥様死亡時）'!E7="","",'CF表（奥様死亡時）'!E7) | F7: =IF('CF表（奥様死亡時）'!F7="","",'CF表（奥様死亡時）'!F7) | G7: =IF('CF表（奥様死亡時）'!G7="","",'CF表（奥様死亡時）'!G7) | H7: =IF('CF表（奥様死亡時）'!H7="","",'CF表（奥様死亡時）'!H7) | I7: =IF('CF表（奥様死亡時）'!I7="","",'CF表（奥様死亡時）'!I7) | ... CW7: =IF('CF表（奥様死亡時）'!CW7="","",'CF表（奥様死亡時）'!CW7)
A8: 子3年齢 | B8: =IF('CF表（奥様死亡時）'!B8="","",'CF表（奥様死亡時）'!B8) | C8: =IF('CF表（奥様死亡時）'!C8="","",'CF表（奥様死亡時）'!C8) | D8: =IF('CF表（奥様死亡時）'!D8="","",'CF表（奥様死亡時）'!D8) | E8: =IF('CF表（奥様死亡時）'!E8="","",'CF表（奥様死亡時）'!E8) | F8: =IF('CF表（奥様死亡時）'!F8="","",'CF表（奥様死亡時）'!F8) | G8: =IF('CF表（奥様死亡時）'!G8="","",'CF表（奥様死亡時）'!G8) | H8: =IF('CF表（奥様死亡時）'!H8="","",'CF表（奥様死亡時）'!H8) | I8: =IF('CF表（奥様死亡時）'!I8="","",'CF表（奥様死亡時）'!I8) | ... CW8: =IF('CF表（奥様死亡時）'!CW8="","",'CF表（奥様死亡時）'!CW8)
A9: 家族年齢
A10: ご主人様収入 | B10: =IF('CF表（奥様死亡時）'!B$3="","",'CF表（奥様死亡時）'!B10/10000) | C10: =IF('CF表（奥様死亡時）'!C$3="","",'CF表（奥様死亡時）'!C10/10000) | D10: =IF('CF表（奥様死亡時）'!D$3="","",'CF表（奥様死亡時）'!D10/10000) | E10: =IF('CF表（奥様死亡時）'!E$3="","",'CF表（奥様死亡時）'!E10/10000) | F10: =IF('CF表（奥様死亡時）'!F$3="","",'CF表（奥様死亡時）'!F10/10000) | G10: =IF('CF表（奥様死亡時）'!G$3="","",'CF表（奥様死亡時）'!G10/10000) | H10: =IF('CF表（奥様死亡時）'!H$3="","",'CF表（奥様死亡時）'!H10/10000) | I10: =IF('CF表（奥様死亡時）'!I$3="","",'CF表（奥様死亡時）'!I10/10000) | ... CW10: =IF('CF表（奥様死亡時）'!CW$3="","",'CF表（奥様死亡時）'!CW10/10000)
A11: 奥様収入 | B11: =IF('CF表（奥様死亡時）'!B$3="","",'CF表（奥様死亡時）'!B11/10000) | C11: =IF('CF表（奥様死亡時）'!C$3="","",'CF表（奥様死亡時）'!C11/10000) | D11: =IF('CF表（奥様死亡時）'!D$3="","",'CF表（奥様死亡時）'!D11/10000) | E11: =IF('CF表（奥様死亡時）'!E$3="","",'CF表（奥様死亡時）'!E11/10000) | F11: =IF('CF表（奥様死亡時）'!F$3="","",'CF表（奥様死亡時）'!F11/10000) | G11: =IF('CF表（奥様死亡時）'!G$3="","",'CF表（奥様死亡時）'!G11/10000) | H11: =IF('CF表（奥様死亡時）'!H$3="","",'CF表（奥様死亡時）'!H11/10000) | I11: =IF('CF表（奥様死亡時）'!I$3="","",'CF表（奥様死亡時）'!I11/10000) | ... CW11: =IF('CF表（奥様死亡時）'!CW$3="","",'CF表（奥様死亡時）'!CW11/10000)
A12: 児童手当 | B12: =IF('CF表（奥様死亡時）'!B$3="","",'CF表（奥様死亡時）'!B12/10000) | C12: =IF('CF表（奥様死亡時）'!C$3="","",'CF表（奥様死亡時）'!C12/10000) | D12: =IF('CF表（奥様死亡時）'!D$3="","",'CF表（奥様死亡時）'!D12/10000) | E12: =IF('CF表（奥様死亡時）'!E$3="","",'CF表（奥様死亡時）'!E12/10000) | F12: =IF('CF表（奥様死亡時）'!F$3="","",'CF表（奥様死亡時）'!F12/10000) | G12: =IF('CF表（奥様死亡時）'!G$3="","",'CF表（奥様死亡時）'!G12/10000) | H12: =IF('CF表（奥様死亡時）'!H$3="","",'CF表（奥様死亡時）'!H12/10000) | I12: =IF('CF表（奥様死亡時）'!I$3="","",'CF表（奥様死亡時）'!I12/10000) | ... CW12: =IF('CF表（奥様死亡時）'!CW$3="","",'CF表（奥様死亡時）'!CW12/10000)
A13: その他収入 | B13: =IF('CF表（奥様死亡時）'!B$3="","",'CF表（奥様死亡時）'!B13/10000) | C13: =IF('CF表（奥様死亡時）'!C$3="","",'CF表（奥様死亡時）'!C13/10000) | D13: =IF('CF表（奥様死亡時）'!D$3="","",'CF表（奥様死亡時）'!D13/10000) | E13: =IF('CF表（奥様死亡時）'!E$3="","",'CF表（奥様死亡時）'!E13/10000) | F13: =IF('CF表（奥様死亡時）'!F$3="","",'CF表（奥様死亡時）'!F13/10000) | G13: =IF('CF表（奥様死亡時）'!G$3="","",'CF表（奥様死亡時）'!G13/10000) | H13: =IF('CF表（奥様死亡時）'!H$3="","",'CF表（奥様死亡時）'!H13/10000) | I13: =IF('CF表（奥様死亡時）'!I$3="","",'CF表（奥様死亡時）'!I13/10000) | ... CW13: =IF('CF表（奥様死亡時）'!CW$3="","",'CF表（奥様死亡時）'!CW13/10000)
A14: ご主人様退職金 | B14: =IF('CF表（奥様死亡時）'!B$3="","",'CF表（奥様死亡時）'!B14/10000) | C14: =IF('CF表（奥様死亡時）'!C$3="","",'CF表（奥様死亡時）'!C14/10000) | D14: =IF('CF表（奥様死亡時）'!D$3="","",'CF表（奥様死亡時）'!D14/10000) | E14: =IF('CF表（奥様死亡時）'!E$3="","",'CF表（奥様死亡時）'!E14/10000) | F14: =IF('CF表（奥様死亡時）'!F$3="","",'CF表（奥様死亡時）'!F14/10000) | G14: =IF('CF表（奥様死亡時）'!G$3="","",'CF表（奥様死亡時）'!G14/10000) | H14: =IF('CF表（奥様死亡時）'!H$3="","",'CF表（奥様死亡時）'!H14/10000) | I14: =IF('CF表（奥様死亡時）'!I$3="","",'CF表（奥様死亡時）'!I14/10000) | ... CW14: =IF('CF表（奥様死亡時）'!CW$3="","",'CF表（奥様死亡時）'!CW14/10000)
A15: 奥様退職金 | B15: =IF('CF表（奥様死亡時）'!B$3="","",'CF表（奥様死亡時）'!B15/10000) | C15: =IF('CF表（奥様死亡時）'!C$3="","",'CF表（奥様死亡時）'!C15/10000) | D15: =IF('CF表（奥様死亡時）'!D$3="","",'CF表（奥様死亡時）'!D15/10000) | E15: =IF('CF表（奥様死亡時）'!E$3="","",'CF表（奥様死亡時）'!E15/10000) | F15: =IF('CF表（奥様死亡時）'!F$3="","",'CF表（奥様死亡時）'!F15/10000) | G15: =IF('CF表（奥様死亡時）'!G$3="","",'CF表（奥様死亡時）'!G15/10000) | H15: =IF('CF表（奥様死亡時）'!H$3="","",'CF表（奥様死亡時）'!H15/10000) | I15: =IF('CF表（奥様死亡時）'!I$3="","",'CF表（奥様死亡時）'!I15/10000) | ... CW15: =IF('CF表（奥様死亡時）'!CW$3="","",'CF表（奥様死亡時）'!CW15/10000)
A16: ご主人様年金収入 | B16: =IF('CF表（奥様死亡時）'!B$3="","",'CF表（奥様死亡時）'!B16/10000) | C16: =IF('CF表（奥様死亡時）'!C$3="","",'CF表（奥様死亡時）'!C16/10000) | D16: =IF('CF表（奥様死亡時）'!D$3="","",'CF表（奥様死亡時）'!D16/10000) | E16: =IF('CF表（奥様死亡時）'!E$3="","",'CF表（奥様死亡時）'!E16/10000) | F16: =IF('CF表（奥様死亡時）'!F$3="","",'CF表（奥様死亡時）'!F16/10000) | G16: =IF('CF表（奥様死亡時）'!G$3="","",'CF表（奥様死亡時）'!G16/10000) | H16: =IF('CF表（奥様死亡時）'!H$3="","",'CF表（奥様死亡時）'!H16/10000) | I16: =IF('CF表（奥様死亡時）'!I$3="","",'CF表（奥様死亡時）'!I16/10000) | ... CW16: =IF('CF表（奥様死亡時）'!CW$3="","",'CF表（奥様死亡時）'!CW16/10000)
A17: 奥様年金収入 | B17: =IF('CF表（奥様死亡時）'!B$3="","",'CF表（奥様死亡時）'!B17/10000) | C17: =IF('CF表（奥様死亡時）'!C$3="","",'CF表（奥様死亡時）'!C17/10000) | D17: =IF('CF表（奥様死亡時）'!D$3="","",'CF表（奥様死亡時）'!D17/10000) | E17: =IF('CF表（奥様死亡時）'!E$3="","",'CF表（奥様死亡時）'!E17/10000) | F17: =IF('CF表（奥様死亡時）'!F$3="","",'CF表（奥様死亡時）'!F17/10000) | G17: =IF('CF表（奥様死亡時）'!G$3="","",'CF表（奥様死亡時）'!G17/10000) | H17: =IF('CF表（奥様死亡時）'!H$3="","",'CF表（奥様死亡時）'!H17/10000) | I17: =IF('CF表（奥様死亡時）'!I$3="","",'CF表（奥様死亡時）'!I17/10000) | ... CW17: =IF('CF表（奥様死亡時）'!CW$3="","",'CF表（奥様死亡時）'!CW17/10000)
A18: 世帯収入合計 | B18: =IF('CF表（奥様死亡時）'!B$3="","",'CF表（奥様死亡時）'!B18/10000) | C18: =IF('CF表（奥様死亡時）'!C$3="","",'CF表（奥様死亡時）'!C18/10000) | D18: =IF('CF表（奥様死亡時）'!D$3="","",'CF表（奥様死亡時）'!D18/10000) | E18: =IF('CF表（奥様死亡時）'!E$3="","",'CF表（奥様死亡時）'!E18/10000) | F18: =IF('CF表（奥様死亡時）'!F$3="","",'CF表（奥様死亡時）'!F18/10000) | G18: =IF('CF表（奥様死亡時）'!G$3="","",'CF表（奥様死亡時）'!G18/10000) | H18: =IF('CF表（奥様死亡時）'!H$3="","",'CF表（奥様死亡時）'!H18/10000) | I18: =IF('CF表（奥様死亡時）'!I$3="","",'CF表（奥様死亡時）'!I18/10000) | ... CW18: =IF('CF表（奥様死亡時）'!CW$3="","",'CF表（奥様死亡時）'!CW18/10000)
A19: 収入
A20: 基本生活費 | B20: =IF('CF表（奥様死亡時）'!B$3="","",'CF表（奥様死亡時）'!B20/10000) | C20: =IF('CF表（奥様死亡時）'!C$3="","",'CF表（奥様死亡時）'!C20/10000) | D20: =IF('CF表（奥様死亡時）'!D$3="","",'CF表（奥様死亡時）'!D20/10000) | E20: =IF('CF表（奥様死亡時）'!E$3="","",'CF表（奥様死亡時）'!E20/10000) | F20: =IF('CF表（奥様死亡時）'!F$3="","",'CF表（奥様死亡時）'!F20/10000) | G20: =IF('CF表（奥様死亡時）'!G$3="","",'CF表（奥様死亡時）'!G20/10000) | H20: =IF('CF表（奥様死亡時）'!H$3="","",'CF表（奥様死亡時）'!H20/10000) | I20: =IF('CF表（奥様死亡時）'!I$3="","",'CF表（奥様死亡時）'!I20/10000) | ... CW20: =IF('CF表（奥様死亡時）'!CW$3="","",'CF表（奥様死亡時）'!CW20/10000)
A21: 住居費 | B21: =IF('CF表（奥様死亡時）'!B$3="","",'CF表（奥様死亡時）'!B21/10000) | C21: =IF('CF表（奥様死亡時）'!C$3="","",'CF表（奥様死亡時）'!C21/10000) | D21: =IF('CF表（奥様死亡時）'!D$3="","",'CF表（奥様死亡時）'!D21/10000) | E21: =IF('CF表（奥様死亡時）'!E$3="","",'CF表（奥様死亡時）'!E21/10000) | F21: =IF('CF表（奥様死亡時）'!F$3="","",'CF表（奥様死亡時）'!F21/10000) | G21: =IF('CF表（奥様死亡時）'!G$3="","",'CF表（奥様死亡時）'!G21/10000) | H21: =IF('CF表（奥様死亡時）'!H$3="","",'CF表（奥様死亡時）'!H21/10000) | I21: =IF('CF表（奥様死亡時）'!I$3="","",'CF表（奥様死亡時）'!I21/10000) | ... CW21: =IF('CF表（奥様死亡時）'!CW$3="","",'CF表（奥様死亡時）'!CW21/10000)
A22: 終身系保険料 | B22: =IF('CF表（奥様死亡時）'!B$3="","",'CF表（奥様死亡時）'!B22/10000) | C22: =IF('CF表（奥様死亡時）'!C$3="","",'CF表（奥様死亡時）'!C22/10000) | D22: =IF('CF表（奥様死亡時）'!D$3="","",'CF表（奥様死亡時）'!D22/10000) | E22: =IF('CF表（奥様死亡時）'!E$3="","",'CF表（奥様死亡時）'!E22/10000) | F22: =IF('CF表（奥様死亡時）'!F$3="","",'CF表（奥様死亡時）'!F22/10000) | G22: =IF('CF表（奥様死亡時）'!G$3="","",'CF表（奥様死亡時）'!G22/10000) | H22: =IF('CF表（奥様死亡時）'!H$3="","",'CF表（奥様死亡時）'!H22/10000) | I22: =IF('CF表（奥様死亡時）'!I$3="","",'CF表（奥様死亡時）'!I22/10000) | ... CW22: =IF('CF表（奥様死亡時）'!CW$3="","",'CF表（奥様死亡時）'!CW22/10000)
A23: 定期系保険料 | B23: =IF('CF表（奥様死亡時）'!B$3="","",'CF表（奥様死亡時）'!B23/10000) | C23: =IF('CF表（奥様死亡時）'!C$3="","",'CF表（奥様死亡時）'!C23/10000) | D23: =IF('CF表（奥様死亡時）'!D$3="","",'CF表（奥様死亡時）'!D23/10000) | E23: =IF('CF表（奥様死亡時）'!E$3="","",'CF表（奥様死亡時）'!E23/10000) | F23: =IF('CF表（奥様死亡時）'!F$3="","",'CF表（奥様死亡時）'!F23/10000) | G23: =IF('CF表（奥様死亡時）'!G$3="","",'CF表（奥様死亡時）'!G23/10000) | H23: =IF('CF表（奥様死亡時）'!H$3="","",'CF表（奥様死亡時）'!H23/10000) | I23: =IF('CF表（奥様死亡時）'!I$3="","",'CF表（奥様死亡時）'!I23/10000) | ... CW23: =IF('CF表（奥様死亡時）'!CW$3="","",'CF表（奥様死亡時）'!CW23/10000)
A24: 教育費 | B24: =IF('CF表（奥様死亡時）'!B$3="","",'CF表（奥様死亡時）'!B24/10000) | C24: =IF('CF表（奥様死亡時）'!C$3="","",'CF表（奥様死亡時）'!C24/10000) | D24: =IF('CF表（奥様死亡時）'!D$3="","",'CF表（奥様死亡時）'!D24/10000) | E24: =IF('CF表（奥様死亡時）'!E$3="","",'CF表（奥様死亡時）'!E24/10000) | F24: =IF('CF表（奥様死亡時）'!F$3="","",'CF表（奥様死亡時）'!F24/10000) | G24: =IF('CF表（奥様死亡時）'!G$3="","",'CF表（奥様死亡時）'!G24/10000) | H24: =IF('CF表（奥様死亡時）'!H$3="","",'CF表（奥様死亡時）'!H24/10000) | I24: =IF('CF表（奥様死亡時）'!I$3="","",'CF表（奥様死亡時）'!I24/10000) | ... CW24: =IF('CF表（奥様死亡時）'!CW$3="","",'CF表（奥様死亡時）'!CW24/10000)
A25: 車関連費 | B25: =IF('CF表（奥様死亡時）'!B$3="","",'CF表（奥様死亡時）'!B25/10000) | C25: =IF('CF表（奥様死亡時）'!C$3="","",'CF表（奥様死亡時）'!C25/10000) | D25: =IF('CF表（奥様死亡時）'!D$3="","",'CF表（奥様死亡時）'!D25/10000) | E25: =IF('CF表（奥様死亡時）'!E$3="","",'CF表（奥様死亡時）'!E25/10000) | F25: =IF('CF表（奥様死亡時）'!F$3="","",'CF表（奥様死亡時）'!F25/10000) | G25: =IF('CF表（奥様死亡時）'!G$3="","",'CF表（奥様死亡時）'!G25/10000) | H25: =IF('CF表（奥様死亡時）'!H$3="","",'CF表（奥様死亡時）'!H25/10000) | I25: =IF('CF表（奥様死亡時）'!I$3="","",'CF表（奥様死亡時）'!I25/10000) | ... CW25: =IF('CF表（奥様死亡時）'!CW$3="","",'CF表（奥様死亡時）'!CW25/10000)
A26: その他支出 | B26: =IF('CF表（奥様死亡時）'!B$3="","",'CF表（奥様死亡時）'!B26/10000) | C26: =IF('CF表（奥様死亡時）'!C$3="","",'CF表（奥様死亡時）'!C26/10000) | D26: =IF('CF表（奥様死亡時）'!D$3="","",'CF表（奥様死亡時）'!D26/10000) | E26: =IF('CF表（奥様死亡時）'!E$3="","",'CF表（奥様死亡時）'!E26/10000) | F26: =IF('CF表（奥様死亡時）'!F$3="","",'CF表（奥様死亡時）'!F26/10000) | G26: =IF('CF表（奥様死亡時）'!G$3="","",'CF表（奥様死亡時）'!G26/10000) | H26: =IF('CF表（奥様死亡時）'!H$3="","",'CF表（奥様死亡時）'!H26/10000) | I26: =IF('CF表（奥様死亡時）'!I$3="","",'CF表（奥様死亡時）'!I26/10000) | ... CW26: =IF('CF表（奥様死亡時）'!CW$3="","",'CF表（奥様死亡時）'!CW26/10000)
A27: 一時支出 | B27: =IF('CF表（奥様死亡時）'!B$3="","",'CF表（奥様死亡時）'!B27/10000) | C27: =IF('CF表（奥様死亡時）'!C$3="","",'CF表（奥様死亡時）'!C27/10000) | D27: =IF('CF表（奥様死亡時）'!D$3="","",'CF表（奥様死亡時）'!D27/10000) | E27: =IF('CF表（奥様死亡時）'!E$3="","",'CF表（奥様死亡時）'!E27/10000) | F27: =IF('CF表（奥様死亡時）'!F$3="","",'CF表（奥様死亡時）'!F27/10000) | G27: =IF('CF表（奥様死亡時）'!G$3="","",'CF表（奥様死亡時）'!G27/10000) | H27: =IF('CF表（奥様死亡時）'!H$3="","",'CF表（奥様死亡時）'!H27/10000) | I27: =IF('CF表（奥様死亡時）'!I$3="","",'CF表（奥様死亡時）'!I27/10000) | ... CW27: =IF('CF表（奥様死亡時）'!CW$3="","",'CF表（奥様死亡時）'!CW27/10000)
A28: 支出合計 | B28: =IF('CF表（奥様死亡時）'!B$3="","",'CF表（奥様死亡時）'!B28/10000) | C28: =IF('CF表（奥様死亡時）'!C$3="","",'CF表（奥様死亡時）'!C28/10000) | D28: =IF('CF表（奥様死亡時）'!D$3="","",'CF表（奥様死亡時）'!D28/10000) | E28: =IF('CF表（奥様死亡時）'!E$3="","",'CF表（奥様死亡時）'!E28/10000) | F28: =IF('CF表（奥様死亡時）'!F$3="","",'CF表（奥様死亡時）'!F28/10000) | G28: =IF('CF表（奥様死亡時）'!G$3="","",'CF表（奥様死亡時）'!G28/10000) | H28: =IF('CF表（奥様死亡時）'!H$3="","",'CF表（奥様死亡時）'!H28/10000) | I28: =IF('CF表（奥様死亡時）'!I$3="","",'CF表（奥様死亡時）'!I28/10000) | ... CW28: =IF('CF表（奥様死亡時）'!CW$3="","",'CF表（奥様死亡時）'!CW28/10000)
A29: 収支・資産 | B29: =IF('CF表（奥様死亡時）'!B$3="","",'CF表（奥様死亡時）'!B29/10000) | C29: =IF('CF表（奥様死亡時）'!C$3="","",'CF表（奥様死亡時）'!C29/10000) | D29: =IF('CF表（奥様死亡時）'!D$3="","",'CF表（奥様死亡時）'!D29/10000) | E29: =IF('CF表（奥様死亡時）'!E$3="","",'CF表（奥様死亡時）'!E29/10000) | F29: =IF('CF表（奥様死亡時）'!F$3="","",'CF表（奥様死亡時）'!F29/10000) | G29: =IF('CF表（奥様死亡時）'!G$3="","",'CF表（奥様死亡時）'!G29/10000) | H29: =IF('CF表（奥様死亡時）'!H$3="","",'CF表（奥様死亡時）'!H29/10000) | I29: =IF('CF表（奥様死亡時）'!I$3="","",'CF表（奥様死亡時）'!I29/10000) | ... CW29: =IF('CF表（奥様死亡時）'!CW$3="","",'CF表（奥様死亡時）'!CW29/10000)
A30: 年間収支 | B30: =IF('CF表（奥様死亡時）'!B$3="","",'CF表（奥様死亡時）'!B30/10000) | C30: =IF('CF表（奥様死亡時）'!C$3="","",'CF表（奥様死亡時）'!C30/10000) | D30: =IF('CF表（奥様死亡時）'!D$3="","",'CF表（奥様死亡時）'!D30/10000) | E30: =IF('CF表（奥様死亡時）'!E$3="","",'CF表（奥様死亡時）'!E30/10000) | F30: =IF('CF表（奥様死亡時）'!F$3="","",'CF表（奥様死亡時）'!F30/10000) | G30: =IF('CF表（奥様死亡時）'!G$3="","",'CF表（奥様死亡時）'!G30/10000) | H30: =IF('CF表（奥様死亡時）'!H$3="","",'CF表（奥様死亡時）'!H30/10000) | I30: =IF('CF表（奥様死亡時）'!I$3="","",'CF表（奥様死亡時）'!I30/10000) | ... CW30: =IF('CF表（奥様死亡時）'!CW$3="","",'CF表（奥様死亡時）'!CW30/10000)
A31: 預貯金残高 | B31: =IF('CF表（奥様死亡時）'!B$3="","",'CF表（奥様死亡時）'!B31/10000) | C31: =IF('CF表（奥様死亡時）'!C$3="","",'CF表（奥様死亡時）'!C31/10000) | D31: =IF('CF表（奥様死亡時）'!D$3="","",'CF表（奥様死亡時）'!D31/10000) | E31: =IF('CF表（奥様死亡時）'!E$3="","",'CF表（奥様死亡時）'!E31/10000) | F31: =IF('CF表（奥様死亡時）'!F$3="","",'CF表（奥様死亡時）'!F31/10000) | G31: =IF('CF表（奥様死亡時）'!G$3="","",'CF表（奥様死亡時）'!G31/10000) | H31: =IF('CF表（奥様死亡時）'!H$3="","",'CF表（奥様死亡時）'!H31/10000) | I31: =IF('CF表（奥様死亡時）'!I$3="","",'CF表（奥様死亡時）'!I31/10000) | ... CW31: =IF('CF表（奥様死亡時）'!CW$3="","",'CF表（奥様死亡時）'!CW31/10000)
... A45: 負債合計（参考） | B45: =IF('CF表（奥様死亡時）'!B$3="","",'CF表（奥様死亡時）'!B45/10000) | C45: =IF('CF表（奥様死亡時）'!C$3="","",'CF表（奥様死亡時）'!C45/10000) | D45: =IF('CF表（奥様死亡時）'!D$3="","",'CF表（奥様死亡時）'!D45/10000) | E45: =IF('CF表（奥様死亡時）'!E$3="","",'CF表（奥様死亡時）'!E45/10000) | F45: =IF('CF表（奥様死亡時）'!F$3="","",'CF表（奥様死亡時）'!F45/10000) | G45: =IF('CF表（奥様死亡時）'!G$3="","",'CF表（奥様死亡時）'!G45/10000) | H45: =IF('CF表（奥様死亡時）'!H$3="","",'CF表（奥様死亡時）'!H45/10000) | I45: =IF('CF表（奥様死亡時）'!I$3="","",'CF表（奥様死亡時）'!I45/10000) | ... CW45: =IF('CF表（奥様死亡時）'!CW$3="","",'CF表（奥様死亡時）'!CW45/10000)

Sheet リスク判定
A1: リスク判定
A3: テーマ | B3: 判定 | C3: 今見る数値
A4: 死亡時 | B4: =C11 | C4: =TEXT(C12,"#,##0")&" 円/年不足" | D4: =IF(B4="安心","今すぐの大きな不足は見えにくい状態です。",IF(B4="注意","一度点検しておきたい状態です。","直近不足または将来の資産不足が見えており、優先して備えを見直したい状態です。"))
A5: 働けない時 | B5: =C17 | C5: =TEXT(C18,"#,##0")&" 円/月不足" | D5: =IF(B5="安心","現状でも一定の備えがある状態です。",IF(B5="注意","働けない時の家計影響を確認したい状態です。","追加の備えを優先して検討したい状態です。"))
A6: 老後 | B6: =C23 | C6: =TEXT(C24,"#,##0")&" 円/年不足" | D6: =IF(B6="安心","現状前提では大きな不足が見えにくい状態です。",IF(B6="注意","積立や支出バランスを見直したい状態です。","今のうちから老後対策を強めたい状態です。"))
A8: 死亡時リスク
A9: 区分 | B9: 項目 | C9: 値
A10: 死亡時
B11: 判定結果 | C11: =IF(OR(MIN('CF表（ご主人様死亡時・万円表示）'!B35:CW35)<0,MIN('CF表（奥様死亡時・万円表示）'!B35:CW35)<0),"要対策",IF(C12=0,"安心",IF(C12<=500000,"注意","要対策")))
B12: 年間平均不足額 | C12: =ROUND(MAX(IFERROR(AVERAGE(FILTER(-'CF表（ご主人様死亡時・万円表示）'!B30:CW30,'CF表（ご主人様死亡時・万円表示）'!B30:CW30<0)),0)*10000,IFERROR(AVERAGE(FILTER(-'CF表（奥様死亡時・万円表示）'!B30:CW30,'CF表（奥様死亡時・万円表示）'!B30:CW30<0)),0)*10000),0)
B13: 必要保障額 | C13: =ROUND(C12*MAX(IF(N(CF表!B6)>0,MAX(22-N(CF表!B6),0),0),IF(N(CF表!B7)>0,MAX(22-N(CF表!B7),0),0),IF(N(CF表!B8)>0,MAX(22-N(CF表!B8),0),0),1),0)
B14: 現在の保障との差額 | C14: =MAX(0,C13-C52)
B15: 次の一手 | C15: =IF(OR(MIN('CF表（ご主人様死亡時・万円表示）'!B35:CW35)<0,MIN('CF表（奥様死亡時・万円表示）'!B35:CW35)<0),"直近だけでなく長期の資産不足が見えているため、年間平均不足額も踏まえて保障額・家計配分・備え方を優先して点検したいです。",IF(C14=0,"現在の保障で大枠はカバーできる可能性があります。","年間平均不足額を踏まえて、必要保障額・保険期間・遺族年金前提を点検したいです。"))
A16: 働けない時のリスク
A17: 働けない時 | B17: 判定結果 | C17: =IF(C18=0,"安心",IF(C18<=50000,"注意","要対策"))
B18: 毎月不足額 | C18: =MAX(0,MAX((N(CF表!B28)/12)-(N(入力データ!$C$30)+N(入力データ!$C$33)/12+N(入力データ!$C$34)+N(入力データ!$C$35)+N(前提条件!$C$55)),(N(CF表!B28)/12)-(N(入力データ!$C$29)+N(入力データ!$C$32)/12+N(入力データ!$C$34)+N(入力データ!$C$35)+N(前提条件!$C$56))))
B19: 必要備え額（65歳まで） | C19: =C18*12*IF(((N(CF表!B28)/12)-(N(入力データ!$C$30)+N(入力データ!$C$33)/12+N(入力データ!$C$34)+N(入力データ!$C$35)+N(前提条件!$C$55)))>=((N(CF表!B28)/12)-(N(入力データ!$C$29)+N(入力データ!$C$32)/12+N(入力データ!$C$34)+N(入力データ!$C$35)+N(前提条件!$C$56))),MAX(65-N(CF表!B4),0),MAX(65-N(CF表!B5),0))
B20: 現在の保障との差額 | C20: =MAX(0,C19-(N(C53)*12*IF(((N(CF表!B28)/12)-(N(入力データ!$C$30)+N(入力データ!$C$33)/12+N(入力データ!$C$34)+N(入力データ!$C$35)+N(前提条件!$C$55)))>=((N(CF表!B28)/12)-(N(入力データ!$C$29)+N(入力データ!$C$32)/12+N(入力データ!$C$34)+N(入力データ!$C$35)+N(前提条件!$C$56))),MAX(65-N(CF表!B4),0),MAX(65-N(CF表!B5),0))))
B21: 次の一手 | C21: =IF(C20=0,"今ある保障や資産で一定の対応余地があります。","就業不能保険・生活防衛資金・固定費の見直しを優先したいです。")
A22: 老後リスク
A23: 老後 | B23: 判定結果 | C23: =IF(C24=0,"安心",IF(C24<=1000000,"注意","要対策"))
B24: 年間不足見込額 | C24: =IFERROR(MAX(0,-MIN(filter(CF表!B30:CW30,(CF表!B4:CW4>=入力データ!$C$111)*(CF表!B5:CW5>=入力データ!$C$111)))),0)
B25: 不足が出始める年齢 | C25: =IF(C24=0,"不足なし",INDEX(filter(CF表!B4:CW4,(CF表!B4:CW4>=入力データ!$C$111)*(CF表!B5:CW5>=入力データ!$C$111)*(CF表!B30:CW30<0)),1)&"歳")
B26: 65歳時点の必要準備額 | C26: =IFERROR(SUM(filter(-CF表!B30:CW30,(CF表!B4:CW4>=65)*(CF表!B5:CW5>=65)*(CF表!B30:CW30<0))),0)
B27: 次の一手 | C27: =IF(C26=0,"現状前提では老後資金の準備余地があります。","積立額・退職時期・老後生活費の前提を一度見直したいです。")
B52: 現在死亡保障総額 | C52: =SUM(入力データ!O5:O20) | D52: 死亡保障の集計値（保険情報から入力ベース）
B53: 現在就業不能保障月額 | C53: =SUM(入力データ!P5:P20)

Sheet グラフ
A1: グラフ
A3: このシートで見ること
A4: ① 通常時・ご主人様死亡時・奥様死亡時の資産推移を比較 ② どのケースで資産が減りやすいかを確認 ③ 面談で優先して整理すべき論点を見つける
A7: ① 3つのケースの保有資産推移
A8: 見どころ：通常時と比べて、ご主人様死亡時・奥様死亡時でどの程度差が出るかを確認します。右肩下がりが続く場合は、保障や家計配分の見直し優先度が高いサインです。
A42: グラフ用データ（Googleスプレッドシートで壊れにくい表）
A43: 下の表をそのまま選択して「挿入 → グラフ」で折れ線グラフを作れます。 PDF用に整える時は、この表を元にCanvaへ反映します。
A46: 年 | B46: 通常時 保有資産合計 | C46: ご主人様死亡時 保有資産合計 | D46: 奥様死亡時 保有資産合計
A47: ='CF表（万円表示）'!B3 | B47: ='CF表（万円表示）'!B35 | C47: ='CF表（ご主人様死亡時・万円表示）'!B35 | D47: ='CF表（奥様死亡時・万円表示）'!B35
A48: ='CF表（万円表示）'!C3 | B48: ='CF表（万円表示）'!C35 | C48: ='CF表（ご主人様死亡時・万円表示）'!C35 | D48: ='CF表（奥様死亡時・万円表示）'!C35
A49: ='CF表（万円表示）'!D3 | B49: ='CF表（万円表示）'!D35 | C49: ='CF表（ご主人様死亡時・万円表示）'!D35 | D49: ='CF表（奥様死亡時・万円表示）'!D35
A50: ='CF表（万円表示）'!E3 | B50: ='CF表（万円表示）'!E35 | C50: ='CF表（ご主人様死亡時・万円表示）'!E35 | D50: ='CF表（奥様死亡時・万円表示）'!E35
A51: ='CF表（万円表示）'!F3 | B51: ='CF表（万円表示）'!F35 | C51: ='CF表（ご主人様死亡時・万円表示）'!F35 | D51: ='CF表（奥様死亡時・万円表示）'!F35
A52: ='CF表（万円表示）'!G3 | B52: ='CF表（万円表示）'!G35 | C52: ='CF表（ご主人様死亡時・万円表示）'!G35 | D52: ='CF表（奥様死亡時・万円表示）'!G35
A53: ='CF表（万円表示）'!H3 | B53: ='CF表（万円表示）'!H35 | C53: ='CF表（ご主人様死亡時・万円表示）'!H35 | D53: ='CF表（奥様死亡時・万円表示）'!H35
A54: ='CF表（万円表示）'!I3 | B54: ='CF表（万円表示）'!I35 | C54: ='CF表（ご主人様死亡時・万円表示）'!I35 | D54: ='CF表（奥様死亡時・万円表示）'!I35
A55: ='CF表（万円表示）'!J3 | B55: ='CF表（万円表示）'!J35 | C55: ='CF表（ご主人様死亡時・万円表示）'!J35 | D55: ='CF表（奥様死亡時・万円表示）'!J35
A56: ='CF表（万円表示）'!K3 | B56: ='CF表（万円表示）'!K35 | C56: ='CF表（ご主人様死亡時・万円表示）'!K35 | D56: ='CF表（奥様死亡時・万円表示）'!K35
A57: ='CF表（万円表示）'!L3 | B57: ='CF表（万円表示）'!L35 | C57: ='CF表（ご主人様死亡時・万円表示）'!L35 | D57: ='CF表（奥様死亡時・万円表示）'!L35
A58: ='CF表（万円表示）'!M3 | B58: ='CF表（万円表示）'!M35 | C58: ='CF表（ご主人様死亡時・万円表示）'!M35 | D58: ='CF表（奥様死亡時・万円表示）'!M35
A59: ='CF表（万円表示）'!N3 | B59: ='CF表（万円表示）'!N35 | C59: ='CF表（ご主人様死亡時・万円表示）'!N35 | D59: ='CF表（奥様死亡時・万円表示）'!N35
A60: ='CF表（万円表示）'!O3 | B60: ='CF表（万円表示）'!O35 | C60: ='CF表（ご主人様死亡時・万円表示）'!O35 | D60: ='CF表（奥様死亡時・万円表示）'!O35
A61: ='CF表（万円表示）'!P3 | B61: ='CF表（万円表示）'!P35 | C61: ='CF表（ご主人様死亡時・万円表示）'!P35 | D61: ='CF表（奥様死亡時・万円表示）'!P35
A62: ='CF表（万円表示）'!Q3 | B62: ='CF表（万円表示）'!Q35 | C62: ='CF表（ご主人様死亡時・万円表示）'!Q35 | D62: ='CF表（奥様死亡時・万円表示）'!Q35
A63: ='CF表（万円表示）'!R3 | B63: ='CF表（万円表示）'!R35 | C63: ='CF表（ご主人様死亡時・万円表示）'!R35 | D63: ='CF表（奥様死亡時・万円表示）'!R35
A64: ='CF表（万円表示）'!S3 | B64: ='CF表（万円表示）'!S35 | C64: ='CF表（ご主人様死亡時・万円表示）'!S35 | D64: ='CF表（奥様死亡時・万円表示）'!S35
A65: ='CF表（万円表示）'!T3 | B65: ='CF表（万円表示）'!T35 | C65: ='CF表（ご主人様死亡時・万円表示）'!T35 | D65: ='CF表（奥様死亡時・万円表示）'!T35
A66: ='CF表（万円表示）'!U3 | B66: ='CF表（万円表示）'!U35 | C66: ='CF表（ご主人様死亡時・万円表示）'!U35 | D66: ='CF表（奥様死亡時・万円表示）'!U35
A67: ='CF表（万円表示）'!V3 | B67: ='CF表（万円表示）'!V35 | C67: ='CF表（ご主人様死亡時・万円表示）'!V35 | D67: ='CF表（奥様死亡時・万円表示）'!V35
A68: ='CF表（万円表示）'!W3 | B68: ='CF表（万円表示）'!W35 | C68: ='CF表（ご主人様死亡時・万円表示）'!W35 | D68: ='CF表（奥様死亡時・万円表示）'!W35
A69: ='CF表（万円表示）'!X3 | B69: ='CF表（万円表示）'!X35 | C69: ='CF表（ご主人様死亡時・万円表示）'!X35 | D69: ='CF表（奥様死亡時・万円表示）'!X35
A70: ='CF表（万円表示）'!Y3 | B70: ='CF表（万円表示）'!Y35 | C70: ='CF表（ご主人様死亡時・万円表示）'!Y35 | D70: ='CF表（奥様死亡時・万円表示）'!Y35
A71: ='CF表（万円表示）'!Z3 | B71: ='CF表（万円表示）'!Z35 | C71: ='CF表（ご主人様死亡時・万円表示）'!Z35 | D71: ='CF表（奥様死亡時・万円表示）'!Z35
A72: ='CF表（万円表示）'!AA3 | B72: ='CF表（万円表示）'!AA35 | C72: ='CF表（ご主人様死亡時・万円表示）'!AA35 | D72: ='CF表（奥様死亡時・万円表示）'!AA35
A73: ='CF表（万円表示）'!AB3 | B73: ='CF表（万円表示）'!AB35 | C73: ='CF表（ご主人様死亡時・万円表示）'!AB35 | D73: ='CF表（奥様死亡時・万円表示）'!AB35
A74: ='CF表（万円表示）'!AC3 | B74: ='CF表（万円表示）'!AC35 | C74: ='CF表（ご主人様死亡時・万円表示）'!AC35 | D74: ='CF表（奥様死亡時・万円表示）'!AC35
A75: ='CF表（万円表示）'!AD3 | B75: ='CF表（万円表示）'!AD35 | C75: ='CF表（ご主人様死亡時・万円表示）'!AD35 | D75: ='CF表（奥様死亡時・万円表示）'!AD35
A76: ='CF表（万円表示）'!AE3 | B76: ='CF表（万円表示）'!AE35 | C76: ='CF表（ご主人様死亡時・万円表示）'!AE35 | D76: ='CF表（奥様死亡時・万円表示）'!AE35
A77: ='CF表（万円表示）'!AF3 | B77: ='CF表（万円表示）'!AF35 | C77: ='CF表（ご主人様死亡時・万円表示）'!AF35 | D77: ='CF表（奥様死亡時・万円表示）'!AF35
A78: ='CF表（万円表示）'!AG3 | B78: ='CF表（万円表示）'!AG35 | C78: ='CF表（ご主人様死亡時・万円表示）'!AG35 | D78: ='CF表（奥様死亡時・万円表示）'!AG35
...

Sheet AI出力用
A1: AI出力用
A3: 1ページ目｜全体サマリー | F3: そのままAIに渡す要約
A4: 区分 | B4: 項目名 | C4: 値 | D4: AI用補足
A5: 1ページ目 | B5: 家庭名 | C5: =入力データ!C6
A6: 1ページ目 | B6: 家族構成 | C6: =IF(入力データ!C17=0,"ご夫婦",IF(入力データ!C17=1,"ご夫婦＋子ども1人","ご夫婦＋子ども"&入力データ!C17&"人"))
A7: 1ページ目 | B7: 住まい区分 | C7: =入力データ!C13
A8: 1ページ目 | B8: 世帯月収 | C8: =入力データ!C29+入力データ!C30+入力データ!C34+入力データ!C35
A9: 1ページ目 | B9: 月間支出 | C9: =CF表!B28/12
A10: 1ページ目 | B10: 現在貯蓄額 | C10: =入力データ!C88+入力データ!C89
A11: 1ページ目 | B11: 保有資産残高 | C11: =CF表!B35
A12: 1ページ目 | B12: 住宅ローン残高 | C12: =入力データ!C95
A13: 1ページ目 | B13: 全体サマリー文 | C13: =IF(CF表!B30>=0,"現状の家計は一定の安定感があります。今後は万一の事態や将来の支出に向けて、備えの優先順位を整理する段階です。","現状の家計は見直し余地があります。まずは日常の収支を整えながら、将来のリスクへの備え方を整理する段階です。")
A14: 1ページ目 | B14: 家計の強み | C14: =IF(CF表!B35>=10000000,"一定の資産があり、今後の選択肢を持ちやすい状態です。","現時点で家計の状況が整理できており、早めに打ち手を考えやすい状態です。")
A15: 1ページ目 | B15: 注意ポイント | C15: =IF(OR(リスク判定!B4="要対策",リスク判定!B5="要対策",リスク判定!B6="要対策"),"万一の収入減少や生活変化が起きた際に、家計負担が大きくなりやすい可能性があります。優先順位をつけて備えを整理することが重要です。","大きな破綻は見えにくいものの、死亡時・働けない時・老後への備えを早めに確認しておくと安心です。")
A17: 2ページ目｜リスクとCFの要点
A18: 区分 | B18: 項目名 | C18: 値 | D18: AI用補足
A19: 2ページ目 | B19: 年間収支 | C19: =CF表!B30
A20: 2ページ目 | B20: 通常時CFの要点 | C20: =IF(CF表!B30>=0,"通常時の家計は大きく崩れておらず、土台は保たれています。","通常時から年間収支に課題があり、まずは家計の整え方を確認したい状態です。")
A21: 2ページ目 | B21: ご主人様死亡時CFの要点 | C21: =IF('CF表（ご主人様死亡時）'!B35<0,"ご主人様に万一のことがあった場合、家計の継続に向けた備えを確認したい状態です。","ご主人様に万一のことがあっても、直ちに大きく崩れにくい見通しです。")
A22: 2ページ目 | B22: 奥様死亡時CFの要点 | C22: =IF('CF表（奥様死亡時）'!B35<0,"奥様に万一のことがあった場合、家計の継続に向けた備えを確認したい状態です。","奥様に万一のことがあっても、直ちに大きく崩れにくい見通しです。")
A23: 2ページ目
A24: 2ページ目 | B24: 死亡時リスク判定 | C24: =リスク判定!B4
A25: 2ページ目 | B25: 働けない時リスク判定 | C25: =リスク判定!B5
A26: 2ページ目 | B26: 老後リスク判定 | C26: =リスク判定!B6
A27: 2ページ目 | B27: 死亡時主要数値 | C27: =リスク判定!C4
A28: 2ページ目 | B28: 働けない時主要数値 | C28: =リスク判定!C5
A29: 2ページ目 | B29: 老後主要数値 | C29: =リスク判定!C6
A30: 2ページ目 | B30: リスク要約文 | C30: =IF(OR(リスク判定!B4="要対策",リスク判定!B5="要対策",リスク判定!B6="要対策"),"通常時は見えにくくても、万一や将来の場面では家計負担が重くなる可能性があります。どこから整えるかを決めることが大切です。","現時点では大きな破綻は見えにくいものの、今のうちに備え方を整理しておくと安心につながります。")
A34: 3ページ目｜改善アクション
A35: 区分 | B35: 項目名 | C35: 値 | D35: AI用補足
A36: 3ページ目 | B36: 優先アクション1 | C36: =IF(リスク判定!B4="要対策","死亡時に家計が崩れやすい部分を先に整理する",IF(リスク判定!B5="要対策","働けない時に備える優先順位を整理する",IF(CF表!B30<0,"通常時の家計収支を整える","将来に向けた備えの優先順位を整理する")))
A37: 3ページ目 | B37: 優先アクション2 | C37: =IF(CF表!B30<0,"固定費と毎月の支出配分を見直す",IF(リスク判定!B5="要対策","就業不能時の備え方を確認する","手元資金と保障のバランスを整える"))
A38: 3ページ目 | B38: 優先アクション3 | C38: =IF(リスク判定!B6="要対策","老後に向けた準備方針を決める",IF(入力データ!C95>0,"住宅ローンと保障のバランスを確認する","積立と貯蓄の役割分担を整える"))
A39: 3ページ目 | B39: 優先順位 | C39: ="1. 今の家計を守る / 2. 大きなリスクに備える / 3. 将来への準備を整える"
A40: 3ページ目 | B40: 進め方の考え方 | C40: =IF(CF表!B30<0,"まずは通常時の赤字要因を整理し、固定費・支出配分・保障内容の順で整えていく進め方が合っています。","現状の家計は大きく崩れていないため、万一の場面で弱くなりやすい部分から順に整えていく進め方が合っています。")
A41: 3ページ目 | B41: FPと一緒に考えること | C41: =IF(入力データ!C95>0,"住宅ローン、保障内容、手元資金のバランスをどう整えるかを一緒に確認します。","家計改善・保障・積立配分をどの順番で整えるかを一緒に確認します。")
A42: 3ページ目 | B42: 面談で確認したいこと | C42: ="今いちばん気になっている不安、見直したい支出、これから優先したいことを確認したいです。"

Sheet 入力データ
A1: 情報入力
A2: 入力ルール：黄色セルを中心に入力 / CF表は左→右に年が進みます / 未使用項目は空欄でOK
A3: 基本情報 | F3: 保険情報（複数行入力）
A4: 大項目 | B4: 項目名 | C4: 入力値 | D4: 補足 | F4: 保険種類 | G4: 対象者 | H4: 被保険者 | I4: 保険会社 | J4: 保険始期 | K4: 保険終期 | L4: 月額保険料 | M4: 受取人 | N4: 払込期間 | O4: 死亡保険金 | P4: 就業不能給付金 | Q4: 入院給付金 | R4: 解約返戻金 | S4: 備考
A5: 基本情報 | B5: 作成日 | C5: =情報入力!C5 | E5: ・未使用項目は空欄でOK | F5: =情報入力!A94 | G5: =情報入力!B94 | H5: =情報入力!C94 | I5: =情報入力!D94 | J5: =情報入力!E94 | K5: =情報入力!F94 | L5: =情報入力!G94 | M5: =情報入力!H94 | N5: 60歳満了 | O5: 30000000 | P5: 0 | Q5: 0 | R5: 0 | S5: 月払
B6: 家庭名 | C6: =情報入力!C6 | E6: ・CF表は左→右に年が進みます | F6: =情報入力!A95 | G6: =情報入力!B95 | H6: =情報入力!C95 | I6: =情報入力!D95 | J6: =情報入力!E95 | K6: =情報入力!F95 | L6: =情報入力!G95 | M6: =情報入力!H95 | N6: 終身払 | O6: 5000000 | P6: 0 | Q6: 0 | R6: 300000 | S6: 死亡保障
B7: 担当者名 | C7: =情報入力!C7 | F7: =情報入力!A96 | G7: =情報入力!B96 | H7: =情報入力!C96 | I7: =情報入力!D96 | J7: =情報入力!E96 | K7: =情報入力!F96 | L7: =情報入力!G96 | M7: =情報入力!H96 | N7: 65歳満了 | O7: 0 | P7: 100000 | Q7: 0 | R7: 0 | S7: 月10万円
B8: ご主人様氏名 | C8: =情報入力!C8 | F8: =情報入力!A97 | G8: =情報入力!B97 | H8: =情報入力!C97 | I8: =情報入力!D97 | J8: =情報入力!E97 | K8: =情報入力!F97 | L8: =情報入力!G97 | M8: =情報入力!H97 | N8: 終身払 | O8: 0 | P8: 0 | Q8: 5000 | R8: 0 | S8: 入院給付金
B9: 奥様氏名 | C9: =情報入力!C9 | F9: =情報入力!A98 | G9: =情報入力!B98 | H9: =情報入力!C98 | I9: =情報入力!D98 | J9: =情報入力!E98 | K9: =情報入力!F98 | L9: =情報入力!G98 | M9: =情報入力!H98
B10: ご主人様生年月日 | C10: =情報入力!C10 | F10: =情報入力!A99 | G10: =情報入力!B99 | H10: =情報入力!C99 | I10: =情報入力!D99 | J10: =情報入力!E99 | K10: =情報入力!F99 | L10: =情報入力!G99 | M10: =情報入力!H99
B11: 奥様生年月日 | C11: =情報入力!C11 | F11: =情報入力!A100 | G11: =情報入力!B100 | H11: =情報入力!C100 | I11: =情報入力!D100 | J11: =情報入力!E100 | K11: =情報入力!F100 | L11: =情報入力!G100 | M11: =情報入力!H100
B12: 都道府県 | C12: =情報入力!C12 | F12: =情報入力!A101 | G12: =情報入力!B101 | H12: =情報入力!C101 | I12: =情報入力!D101 | J12: =情報入力!E101 | K12: =情報入力!F101 | L12: =情報入力!G101 | M12: =情報入力!H101
B13: 住まい区分 | C13: =情報入力!C13
A15: 家族情報
A16: 大項目 | B16: 項目名 | C16: 入力値 | D16: 補足
A17: 家族情報 | B17: 子ども人数 | C17: =情報入力!C17
B18: 子1氏名 | C18: =情報入力!C18
B19: 子1生年月日 | C19: =情報入力!C19
B20: 子2氏名 | C20: =情報入力!C20
B21: 子2生年月日 | C21: =情報入力!C21
B22: 子3氏名 | C22: =情報入力!C22
A23: 教育費情報（複数行入力） | F23: 教育費情報（子ども別）
F24: 子ども名 | G24: 幼稚園区分 | H24: 小学校区分 | I24: 中学校区分 | J24: 高校区分 | K24: 大学区分 | L24: 大学通学
A25: 収入情報 | F25: =情報入力!A106 | G25: =情報入力!B106 | H25: =情報入力!C106 | I25: =情報入力!D106 | J25: =情報入力!E106 | K25: =情報入力!F106 | L25: =情報入力!G106
A26: 大項目 | B26: 項目名 | C26: 入力値 | D26: 補足 | F26: =情報入力!A107 | G26: =情報入力!B107 | H26: =情報入力!C107 | I26: =情報入力!D107 | J26: =情報入力!E107 | K26: =情報入力!F107 | L26: =情報入力!G107
A27: 収入情報 | B27: ご主人様勤務形態 | C27: =情報入力!C26 | F27: =情報入力!A108 | G27: =情報入力!B108 | H27: =情報入力!C108 | I27: =情報入力!D108 | J27: =情報入力!E108 | K27: =情報入力!F108 | L27: =情報入力!G108
B28: 奥様勤務形態 | C28: =情報入力!C27 | F28: =情報入力!A109 | G28: =情報入力!B109 | H28: =情報入力!C109 | I28: =情報入力!D109 | J28: =情報入力!E109 | K28: =情報入力!F109 | L28: =情報入力!G109
B29: ご主人様手取り月収 | C29: =情報入力!C28
B30: 奥様手取り月収 | C30: =情報入力!C29
B31: ボーナス有無 | C31: =情報入力!C30
B32: ご主人様年間賞与手取 | C32: =情報入力!C31
B33: 奥様年間賞与手取 | C33: =情報入力!C32
B34: 児童手当月額 | C34: =IFERROR(ROUND((IF($C$17>=1,IF(YEAR(DATE(YEAR($C$5),12,31))-YEAR($C$19)-IF(DATE(YEAR($C$5),12,31)<DATE(YEAR($C$5),MONTH($C$19),DAY($C$19)),1,0)<3,15000,10000),0)+IF($C$17>=2,IF(2>=3,30000,IF(YEAR(DATE(YEAR($C$5),12,31))-YEAR($C$21)-IF(DATE(YEAR($C$5),12,31)<DATE(YEAR($C$5),MONTH($C$21),DAY($C$21)),1,0)<3,15000,10000)),0)+IF($C$17>=3,30000,0))/MAX($C$17,1),0),0)
B35: その他定期収入月額 | C35: =IF(情報入力!C34="",0,情報入力!C34)
B36: ご主人様退職金見込額 | C36: =IF(情報入力!C35="",0,情報入力!C35)
B37: 奥様退職金見込額 | C37: =IF(情報入力!C36="",0,情報入力!C36)
A39: 支出情報（月額）
A40: 大項目 | B40: 項目名 | C40: 入力値 | D40: 補足
A41: 支出情報（月額） | B41: 食費 | C41: =情報入力!C40
B42: 日用品費 | C42: =情報入力!C41
...

Sheet CF表
A1: CF表（年次CF / 左→右に年が進む）
A2: 試算終了年 | B2: =MAX(IF(入力データ!$C$10<>"",YEAR(入力データ!$C$10)+100,0),IF(入力データ!$C$11<>"",YEAR(入力データ!$C$11)+100,0))
A3: 年 | B3: =IF(YEAR(入力データ!$C$5)>$B$2,"",YEAR(入力データ!$C$5)) | C3: =IF(B3="","",IF(B3+1>$B$2,"",B3+1)) | D3: =IF(C3="","",IF(C3+1>$B$2,"",C3+1)) | E3: =IF(D3="","",IF(D3+1>$B$2,"",D3+1)) | F3: =IF(E3="","",IF(E3+1>$B$2,"",E3+1)) | G3: =IF(F3="","",IF(F3+1>$B$2,"",F3+1)) | H3: =IF(G3="","",IF(G3+1>$B$2,"",G3+1)) | I3: =IF(H3="","",IF(H3+1>$B$2,"",H3+1)) | J3: =IF(I3="","",IF(I3+1>$B$2,"",I3+1)) | ... CW3: =IF(CV3="","",IF(CV3+1>$B$2,"",CV3+1))
A4: ご主人様年齢 | B4: =IF(B$3="","",IF(入力データ!$C$10="","",YEAR(DATE(B$3,12,31))-YEAR(入力データ!$C$10)-IF(DATE(B$3,12,31)<DATE(B$3,MONTH(入力データ!$C$10),DAY(入力データ!$C$10)),1,0))) | C4: =IF(C$3="","",IF(入力データ!$C$10="","",YEAR(DATE(C$3,12,31))-YEAR(入力データ!$C$10)-IF(DATE(C$3,12,31)<DATE(C$3,MONTH(入力データ!$C$10),DAY(入力データ!$C$10)),1,0))) | D4: =IF(D$3="","",IF(入力データ!$C$10="","",YEAR(DATE(D$3,12,31))-YEAR(入力データ!$C$10)-IF(DATE(D$3,12,31)<DATE(D$3,MONTH(入力データ!$C$10),DAY(入力データ!$C$10)),1,0))) | E4: =IF(E$3="","",IF(入力データ!$C$10="","",YEAR(DATE(E$3,12,31))-YEAR(入力データ!$C$10)-IF(DATE(E$3,12,31)<DATE(E$3,MONTH(入力データ!$C$10),DAY(入力データ!$C$10)),1,0))) | F4: =IF(F$3="","",IF(入力データ!$C$10="","",YEAR(DATE(F$3,12,31))-YEAR(入力データ!$C$10)-IF(DATE(F$3,12,31)<DATE(F$3,MONTH(入力データ!$C$10),DAY(入力データ!$C$10)),1,0))) | G4: =IF(G$3="","",IF(入力データ!$C$10="","",YEAR(DATE(G$3,12,31))-YEAR(入力データ!$C$10)-IF(DATE(G$3,12,31)<DATE(G$3,MONTH(入力データ!$C$10),DAY(入力データ!$C$10)),1,0))) | H4: =IF(H$3="","",IF(入力データ!$C$10="","",YEAR(DATE(H$3,12,31))-YEAR(入力データ!$C$10)-IF(DATE(H$3,12,31)<DATE(H$3,MONTH(入力データ!$C$10),DAY(入力データ!$C$10)),1,0))) | I4: =IF(I$3="","",IF(入力データ!$C$10="","",YEAR(DATE(I$3,12,31))-YEAR(入力データ!$C$10)-IF(DATE(I$3,12,31)<DATE(I$3,MONTH(入力データ!$C$10),DAY(入力データ!$C$10)),1,0))) | ... CW4: =IF(CW$3="","",IF(入力データ!$C$10="","",YEAR(DATE(CW$3,12,31))-YEAR(入力データ!$C$10)-IF(DATE(CW$3,12,31)<DATE(CW$3,MONTH(入力データ!$C$10),DAY(入力データ!$C$10)),1,0)))
A5: 奥様年齢 | B5: =IF(B$3="","",IF(入力データ!$C$11="","",YEAR(DATE(B$3,12,31))-YEAR(入力データ!$C$11)-IF(DATE(B$3,12,31)<DATE(B$3,MONTH(入力データ!$C$11),DAY(入力データ!$C$11)),1,0))) | C5: =IF(C$3="","",IF(入力データ!$C$11="","",YEAR(DATE(C$3,12,31))-YEAR(入力データ!$C$11)-IF(DATE(C$3,12,31)<DATE(C$3,MONTH(入力データ!$C$11),DAY(入力データ!$C$11)),1,0))) | D5: =IF(D$3="","",IF(入力データ!$C$11="","",YEAR(DATE(D$3,12,31))-YEAR(入力データ!$C$11)-IF(DATE(D$3,12,31)<DATE(D$3,MONTH(入力データ!$C$11),DAY(入力データ!$C$11)),1,0))) | E5: =IF(E$3="","",IF(入力データ!$C$11="","",YEAR(DATE(E$3,12,31))-YEAR(入力データ!$C$11)-IF(DATE(E$3,12,31)<DATE(E$3,MONTH(入力データ!$C$11),DAY(入力データ!$C$11)),1,0))) | F5: =IF(F$3="","",IF(入力データ!$C$11="","",YEAR(DATE(F$3,12,31))-YEAR(入力データ!$C$11)-IF(DATE(F$3,12,31)<DATE(F$3,MONTH(入力データ!$C$11),DAY(入力データ!$C$11)),1,0))) | G5: =IF(G$3="","",IF(入力データ!$C$11="","",YEAR(DATE(G$3,12,31))-YEAR(入力データ!$C$11)-IF(DATE(G$3,12,31)<DATE(G$3,MONTH(入力データ!$C$11),DAY(入力データ!$C$11)),1,0))) | H5: =IF(H$3="","",IF(入力データ!$C$11="","",YEAR(DATE(H$3,12,31))-YEAR(入力データ!$C$11)-IF(DATE(H$3,12,31)<DATE(H$3,MONTH(入力データ!$C$11),DAY(入力データ!$C$11)),1,0))) | I5: =IF(I$3="","",IF(入力データ!$C$11="","",YEAR(DATE(I$3,12,31))-YEAR(入力データ!$C$11)-IF(DATE(I$3,12,31)<DATE(I$3,MONTH(入力データ!$C$11),DAY(入力データ!$C$11)),1,0))) | ... CW5: =IF(CW$3="","",IF(入力データ!$C$11="","",YEAR(DATE(CW$3,12,31))-YEAR(入力データ!$C$11)-IF(DATE(CW$3,12,31)<DATE(CW$3,MONTH(入力データ!$C$11),DAY(入力データ!$C$11)),1,0)))
